Workbook

Sheet 1. Test Setup
B2: Fortnite Power-Plan FPS Benchmark | Test Setup & Methodology
B3: Validation of Windows power-plan performance, integrity-first, repeated captures
B5: 1 · System Under Test (Hardware) | E5: HOW TO READ THIS WORKBOOK
B6: CPU | C6: Intel(R) Core(TM) i5-10400F CPU @ 2.90GHz (6 cores / 12 threads) | E6: Sheet 2 - Glossary
B7: GPU | C7: AMD Radeon RX 5700 XT | E7: Plain-language explanation of every metric and statistical term used in this workbook. Start here if any column name is unclear.
B8: Display | C8: 1920x1080 @ 144 Hz
B9: Machine name | C9: WORKSTATION | E9: Sheet 3 - Raw Data
E10: Every individual run (195 rows): measured Avg / 1% low / 0.1% low FPS, frame-time statistics, plus a per-second FPS time-series for each run.
B11: 2 · Operating System & Power Plans Tested
B12: Operating System | C12: Windows 11 Pro (Build 26200) | E12: Sheet 4 - Statistical Analysis
B13: What was changed | C13: Windows Power Plan only — 39 different power plans tested back-to-back on the identical OS image and hardware. No other variable was altered between conditions. | E13: Per-plan aggregates computed with live Excel formulas from Sheet 3: mean +/- SD, CV%, 95% confidence interval, and a Welch t-test vs the top plan.
B14: Power plans tested | C14: 39 plans, incl. 2 Microsoft stock references (MSFT High Performance, MSFT Ultimate Performance)
B15: Stock references | C15: 'MSFT-High-Performance' and 'MSFT-UltimatePerformance' are Microsoft's built-in Windows power plans, kept as neutral reference points. | E15: Sheet 5 - Graphs
E16: All charts collected on one sheet, each with a short caption explaining what it shows and how to read it.
B17: 3 · Workload / Scene
B18: Game | C18: FortniteClient-Win64-Shipping.exe (Fortnite) | E18: Sheet 6 - Verdicts
B19: Test scenario | C19: Custom 1v1 map, fixed STATIC scene. The same static scene was captured repeatedly under each power plan so the only difference between captures is the power plan itself. | E19: One row per plan with a data-driven advisory note. The final VERDICT column is yours to fill (dropdown).
B20: Why static scene | C20: A static, reproducible scene removes gameplay randomness, isolating the power-plan effect and maximising measurement integrity.
E21: Statistical stance
B22: 4 · Capture Tool & Protocol | E22: Differences are only called 'real' when supported by the t-test (p<0.05). Plans statistically tied with the leader are flagged so you don't over-read noise.
B23: Capture tool | C23: Custom in-house FPS capture tool (Capture-FPS.ps1 v2.0.0), built by the tester on top of Intel PresentMon.
B24: Measurement engine | C24: Intel PresentMon 2.4.1 (PresentMon v2 / v2 style) — industry-standard frame-time capture.
B25: Captures per plan | C25: 5 repeated captures (runs) per power plan
B26: Capture length | C26: 65s timed capture each
B27: Warm-up discarded | C27: First 5s of every capture discarded as warm-up → 60s analysed per run
B28: Inter-capture delay | C28: ~5 s settle delay between captures for accuracy/consistency
B29: Primary signal | C29: MsBetweenPresents (present-to-present frame time); FPS = 1000 / frame time
B30: Present mode observed | C30: Hardware: Independent Flip on 100% of runs (clean flip path, no present-mode collapse)
B32: 5 · Dataset Integrity Summary
B33: Total valid runs analysed | C33: 195 (39 plans × 5 runs)
B34: Total frames analysed | C34: 2,684,840
B35: Excluded captures | C35: 1 failed PresentMon capture (Bitsum run @16:33:38, PresentMon error) — excluded; replaced by a valid re-run.
B36: Runs with dropped frames | C36: 2 of 195 runs (negligible)
B37: Run-to-run repeatability | C37: Median per-plan CV = 0.41% · pooled within-run CV = 1.10% → very stable
B38: Capture dates | C38: 2026-06-24 (single session)

Sheet 2. Glossary
B2: Glossary - what each metric and term means, in plain language
B3: Read 'Better when' as the direction that is good. 'Found in' points to the sheet/column where the value lives.
B5: A. Speed & smoothness metrics (per run on Raw Data; averaged on Statistical Analysis)
B6: Term | C6: Plain-language meaning | D6: Better when | E6: Found in
B7: Avg FPS | C7: Average frames per second across the whole 60-second test. The single most-quoted speed number. | D7: Higher | E7: Raw Data H / Stats E
B8: Median FPS | C8: The middle FPS value - half the frames are faster, half slower. Less swayed by rare spikes than the average. | D8: Higher | E8: Raw Data I / Stats I
B9: 1% Low FPS (P99) | C9: Your FPS during the worst moments: the value that 99% of frames beat. Captures dips and stutters. | D9: Higher | E9: Raw Data J / Stats J
B10: 0.1% Low FPS (P99.9) | C10: Even rarer worst moments - the deepest dips (slowest 0.1% of frames). Very sensitive to occasional hitches. | D10: Higher | E10: Raw Data K / Stats K
B11: 1% Low (worst-1% avg) | C11: Alternative method (NVIDIA FrameView style): the average FPS of the slowest 1% of frames, not a single percentile point. | D11: Higher | E11: Raw Data L / Stats L
B12: 0.1% Low (worst-0.1% avg) | C12: Same idea, for the slowest 0.1% of frames. | D12: Higher | E12: Raw Data M / Stats M
B13: Min FPS / Max FPS | C13: The single slowest (Min) and fastest (Max) frame in the test, expressed as FPS. Min is a worst-case snapshot. | D13: Higher (Min) | E13: Raw Data N / O
B14: Frame time (ms) | C14: Time to make one frame, in milliseconds. FPS = 1000 / frame time. 8.33 ms = 120 FPS; 4.17 ms = 240 FPS. | D14: Lower | E14: underlying signal
B15: Frametime mean / SD (ms) | C15: Mean = average time per frame. SD = how much frame times vary. High SD means uneven pacing you feel as jitter. | D15: Lower | E15: Raw Data P / Q
B16: Frametime CV % | C16: SD as a percentage of the mean - frame-pacing smoothness on a comparable scale across plans. | D16: Lower | E16: Raw Data R / Stats P
B17: Stutter % | C17: Share of frames that took more than twice as long as the frame before - i.e. visible hitches. | D17: Lower | E17: Raw Data S
B18: % frames <120 FPS | C18: Share of frames that dropped below 120 FPS. On a 144 Hz screen, fewer is better. | D18: Lower | E18: Raw Data T
B20: B. Capture & data-integrity terms
B21: Term | C21: Plain-language meaning | D21: Better when | E21: Found in
B22: Run | C22: One single 60-second capture. Each plan was tested 5 times (Run 1-5) to average out luck. | D22: Neutral | E22: Raw Data B
B23: Frames (analysed) | C23: How many frames were measured in the 60-second window (after warm-up was removed). More frames = more data. | D23: Higher | E23: Raw Data D
B24: Window (s) | C24: Length of the analysed slice - about 60 s for every run by design, so all plans are compared over equal time. | D24: =60 -> 60 | E24: Raw Data E
B25: Warm-up | C25: First 5 s of each capture, thrown away so loading/settling does not pollute the result. | D25: Neutral | E25: method
B26: Dropped | C26: Frames the system discarded (never shown on screen). Near zero means a clean capture. | D26: Lower (0 ideal) | E26: Raw Data F
B27: Present Mode | C27: How finished frames reach the screen. 'Hardware: Independent Flip' is the fast, clean path - it was used on 100% of runs here. | D27: Neutral | E27: Raw Data G
B28: Per-second FPS (s01..s60) | C28: FPS measured in each 1-second slice of a run. Lets you see stability over time inside one capture (see Graph 4). | D28: Flatter=steadier | E28: Raw Data s01-s60
B30: C. Statistical terms (Statistical Analysis sheet)
B31: Term | C31: Plain-language meaning | D31: Better when | E31: Found in
B32: Mean | C32: The plain average of the 5 runs for a given metric. | D32: Neutral | E32: Stats E, I-Q
B33: +/- SD (Standard Deviation) | C33: Typical spread of the 5 runs around their mean. Small SD = the runs agreed closely. | D33: Lower | E33: Stats F
B34: CV % (Coeff. of Variation) | C34: SD divided by mean, as a %. Fair way to compare consistency between fast and slow plans. | D34: Lower | E34: Stats G
B35: 95% CI +/- (Confidence Interval) | C35: The mean is reliable to about plus/minus this much. If two plans' (mean +/- CI) overlap, they may not truly differ. | D35: Smaller | E35: Stats H
B36: Delta vs top (FPS / %) | C36: How far this plan sits below the #1 plan, in FPS and in percent. | D36: Closer to 0 | E36: Stats R / S
B37: Welch p vs top | C37: Probability the gap to the #1 plan is just random luck. p < 0.05 = the gap is real; higher = could be noise. | D37: Neutral | E37: Stats T
B38: Sig? (Significance) | C38: 'yes' = statistically slower than #1 (p<0.05). 'tie' = not separable from #1, i.e. effectively as good. | D38: 'tie' near top | E38: Stats U
B39: Repeatability | C39: Word rating from CV%: Excellent <1%, Good <2%, Fair <4%, Poor >=4%. How trustworthy the plan's result is. | D39: Excellent | E39: Stats V
B40: ANOVA (F, p) | C40: One overall test: 'do the plans really differ at all, beyond run-to-run noise?' A tiny p (here ~3e-70) means yes, clearly. | D40: Neutral | E40: Stats summary
B41: MSFT stock | C41: Microsoft's built-in Windows plans (High Performance, Ultimate Performance), kept as neutral reference points. | D41: Neutral | E41: highlighted rows

Sheet 3. Raw Data
A1: Plan | B1: Run | C1: Windows Power Scheme | D1: Frames (analysed) | E1: Window (s) | F1: Dropped | G1: Present Mode | H1: Avg FPS | I1: Median FPS | J1: 1% Low FPS (P99) | K1: 0.1% Low FPS (P99.9) | L1: 1% Low FPS (worst-1% avg) | M1: 0.1% Low FPS (worst-0.1% avg) | N1: Min FPS | O1: Max FPS | P1: Frametime mean (ms) | Q1: Frametime SD (ms) | R1: Frametime CV (%) | S1: Stutter (%) | T1: % frames <120 FPS | U1: Per-second FPS series → | V1: s01 | W1: s02 | X1: s03 | Y1: s04 | Z1: s05 | AA1: s06 | AB1: s07 | AC1: s08 | AD1: s09 | AE1: s10 | AF1: s11 | AG1: s12 | AH1: s13 | AI1: s14 | AJ1: s15 | AK1: s16 | AL1: s17 | AM1: s18 | AN1: s19 | AO1: s20 | AP1: s21 | AQ1: s22 | AR1: s23 | AS1: s24 | AT1: s25 | AU1: s26 | AV1: s27 | AW1: s28 | AX1: s29 | AY1: s30 | AZ1: s31 | BA1: s32 | BB1: s33 | BC1: s34 | BD1: s35 | BE1: s36 | BF1: s37 | BG1: s38 | BH1: s39 | BI1: s40 | BJ1: s41 | BK1: s42 | BL1: s43 | BM1: s44 | BN1: s45 | BO1: s46 | BP1: s47 | BQ1: s48 | BR1: s49 | BS1: s50 | BT1: s51 | BU1: s52 | BV1: s53 | BW1: s54 | BX1: s55 | BY1: s56 | BZ1: s57 | CA1: s58 | CB1: s59 | CC1: s60
A2: Arsenza-PowerPlan-INTEL | B2: 1 | C2: ARSENZA LOW LATENCY (INTEL THREAD DIRECTOR FIX | D2: 14500 | E2: 59.995562 | F2: 0 | G2: Hardware: Independent Flip | H2: 241.68454 | I2: 245.60369 | J2: 191.04361 | K2: 165.77356 | L2: 169.13521 | M2: 92.828245 | N2: 40.762753 | O2: 406.43798 | P2: 4.137625 | Q2: 0.41844509 | R2: 10.113171 | S2: 0.02758811 | T2: 0.020689655 | V2: 247 | W2: 242 | X2: 245 | Y2: 243 | Z2: 244 | AA2: 241 | AB2: 235 | AC2: 245 | AD2: 244 | AE2: 243 | AF2: 242 | AG2: 243 | AH2: 242 | AI2: 241 | AJ2: 244 | AK2: 245 | AL2: 245 | AM2: 247 | AN2: 245 | AO2: 241 | AP2: 238 | AQ2: 244 | AR2: 246 | AS2: 244 | AT2: 245 | AU2: 246 | AV2: 244 | AW2: 246 | AX2: 244 | AY2: 241 | AZ2: 244 | BA2: 244 | BB2: 245 | BC2: 245 | BD2: 248 | BE2: 242 | BF2: 243 | BG2: 245 | BH2: 244 | BI2: 240 | BJ2: 244 | BK2: 244 | BL2: 245 | BM2: 248 | BN2: 243 | BO2: 243 | BP2: 239 | BQ2: 243 | BR2: 245 | BS2: 239 | BT2: 234 | BU2: 234 | BV2: 232 | BW2: 233 | BX2: 232 | BY2: 231 | BZ2: 230 | CA2: 232 | CB2: 235 | CC2: 232
A3: Arsenza-PowerPlan-INTEL | B3: 2 | C3: ARSENZA LOW LATENCY (INTEL THREAD DIRECTOR FIX | D3: 14602 | E3: 59.991077 | F3: 0 | G3: Hardware: Independent Flip | H3: 243.40287 | I3: 247.13936 | J3: 194.26178 | K3: 173.10608 | L3: 169.36795 | M3: 75.597218 | N3: 38.553622 | O3: 433.74539 | P3: 4.108415 | Q3: 0.41389269 | R3: 10.074267 | S3: 0.03424423 | T3: 0.034241885 | V3: 244 | W3: 245 | X3: 247 | Y3: 245 | Z3: 246 | AA3: 241 | AB3: 246 | AC3: 240 | AD3: 244 | AE3: 244 | AF3: 245 | AG3: 243 | AH3: 243 | AI3: 248 | AJ3: 245 | AK3: 245 | AL3: 245 | AM3: 245 | AN3: 243 | AO3: 236 | AP3: 247 | AQ3: 244 | AR3: 244 | AS3: 247 | AT3: 244 | AU3: 241 | AV3: 244 | AW3: 243 | AX3: 244 | AY3: 246 | AZ3: 245 | BA3: 245 | BB3: 246 | BC3: 242 | BD3: 244 | BE3: 242 | BF3: 243 | BG3: 244 | BH3: 247 | BI3: 243 | BJ3: 245 | BK3: 242 | BL3: 240 | BM3: 242 | BN3: 243 | BO3: 240 | BP3: 244 | BQ3: 240 | BR3: 243 | BS3: 246 | BT3: 243 | BU3: 242 | BV3: 242 | BW3: 235 | BX3: 240 | BY3: 238 | BZ3: 242 | CA3: 244 | CB3: 243 | CC3: 243
A4: Arsenza-PowerPlan-INTEL | B4: 3 | C4: ARSENZA LOW LATENCY (INTEL THREAD DIRECTOR FIX | D4: 14530 | E4: 59.990604 | F4: 0 | G4: Hardware: Independent Flip | H4: 242.2046 | I4: 246.19324 | J4: 193.38619 | K4: 173.43444 | L4: 175.22138 | M4: 106.46226 | N4: 45.936672 | O4: 479.66232 | P4: 4.1287408 | Q4: 0.40479615 | R4: 9.8043488 | S4: 0.027531145 | T4: 0.013764625 | V4: 240 | W4: 244 | X4: 241 | Y4: 240 | Z4: 245 | AA4: 240 | AB4: 242 | AC4: 243 | AD4: 242 | AE4: 241 | AF4: 234 | AG4: 245 | AH4: 242 | AI4: 245 | AJ4: 245 | AK4: 243 | AL4: 241 | AM4: 244 | AN4: 244 | AO4: 239 | AP4: 238 | AQ4: 244 | AR4: 244 | AS4: 241 | AT4: 240 | AU4: 243 | AV4: 240 | AW4: 242 | AX4: 245 | AY4: 245 | AZ4: 244 | BA4: 245 | BB4: 240 | BC4: 245 | BD4: 244 | BE4: 242 | BF4: 242 | BG4: 242 | BH4: 244 | BI4: 241 | BJ4: 232 | BK4: 242 | BL4: 241 | BM4: 243 | BN4: 243 | BO4: 242 | BP4: 244 | BQ4: 244 | BR4: 244 | BS4: 241 | BT4: 239 | BU4: 243 | BV4: 237 | BW4: 242 | BX4: 240 | BY4: 242 | BZ4: 246 | CA4: 243 | CB4: 247 | CC4: 244
A5: Arsenza-PowerPlan-INTEL | B5: 4 | C5: ARSENZA LOW LATENCY (INTEL THREAD DIRECTOR FIX | D5: 14494 | E5: 59.996263 | F5: 0 | G5: Hardware: Independent Flip | H5: 241.58171 | I5: 245.52229 | J5: 191.92742 | K5: 168.28414 | L5: 169.69116 | M5: 91.937115 | N5: 43.801056 | O5: 469.41745 | P5: 4.1393862 | Q5: 0.41541685 | R5: 10.035711 | S5: 0.020699648 | T5: 0.027597627 | V5: 245 | W5: 245 | X5: 244 | Y5: 246 | Z5: 243 | AA5: 241 | AB5: 239 | AC5: 241 | AD5: 242 | AE5: 242 | AF5: 244 | AG5: 240 | AH5: 241 | AI5: 239 | AJ5: 243 | AK5: 244 | AL5: 239 | AM5: 240 | AN5: 241 | AO5: 240 | AP5: 243 | AQ5: 245 | AR5: 243 | AS5: 245 | AT5: 244 | AU5: 245 | AV5: 228 | AW5: 239 | AX5: 243 | AY5: 245 | AZ5: 244 | BA5: 243 | BB5: 244 | BC5: 242 | BD5: 231 | BE5: 244 | BF5: 240 | BG5: 245 | BH5: 243 | BI5: 244 | BJ5: 243 | BK5: 237 | BL5: 246 | BM5: 244 | BN5: 245 | BO5: 246 | BP5: 240 | BQ5: 248 | BR5: 244 | BS5: 243 | BT5: 245 | BU5: 238 | BV5: 234 | BW5: 235 | BX5: 234 | BY5: 232 | BZ5: 231 | CA5: 242 | CB5: 244 | CC5: 244
A6: Arsenza-PowerPlan-INTEL | B6: 5 | C6: ARSENZA LOW LATENCY (INTEL THREAD DIRECTOR FIX | D6: 14472 | E6: 59.994235 | F6: 0 | G6: Hardware: Independent Flip | H6: 241.22318 | I6: 245.01096 | J6: 192.34242 | K6: 163.83908 | L6: 164.71217 | M6: 74.505766 | N6: 42.775076 | O6: 440.06337 | P6: 4.1455387 | Q6: 0.422052 | R6: 10.180872 | S6: 0.02764149 | T6: 0.034549475 | V6: 244 | W6: 238 | X6: 234 | Y6: 239 | Z6: 245 | AA6: 242 | AB6: 243 | AC6: 243 | AD6: 243 | AE6: 247 | AF6: 243 | AG6: 242 | AH6: 237 | AI6: 232 | AJ6: 241 | AK6: 243 | AL6: 242 | AM6: 246 | AN6: 240 | AO6: 244 | AP6: 242 | AQ6: 236 | AR6: 243 | AS6: 239 | AT6: 241 | AU6: 243 | AV6: 239 | AW6: 236 | AX6: 244 | AY6: 241 | AZ6: 245 | BA6: 241 | BB6: 245 | BC6: 245 | BD6: 242 | BE6: 242 | BF6: 243 | BG6: 241 | BH6: 241 | BI6: 244 | BJ6: 243 | BK6: 240 | BL6: 243 | BM6: 241 | BN6: 241 | BO6: 241 | BP6: 241 | BQ6: 241 | BR6: 242 | BS6: 241 | BT6: 243 | BU6: 236 | BV6: 239 | BW6: 239 | BX6: 240 | BY6: 241 | BZ6: 242 | CA6: 237 | CB6: 235 | CC6: 245
A7: EndGame-PowerPlan | B7: 1 | C7: Endgame Performance | D7: 14379 | E7: 60.008226 | F7: 0 | G7: Hardware: Independent Flip | H7: 239.61715 | I7: 243.19658 | J7: 189.24441 | K7: 166.62816 | L7: 168.65361 | M7: 90.168073 | N7: 38.093932 | O7: 422.60068 | P7: 4.173324 | Q7: 0.43583164 | R7: 10.443273 | S7: 0.027820281 | T7: 0.02086376 | V7: 233 | W7: 233 | X7: 242 | Y7: 242 | Z7: 240 | AA7: 241 | AB7: 242 | AC7: 236 | AD7: 239 | AE7: 241 | AF7: 239 | AG7: 239 | AH7: 239 | AI7: 236 | AJ7: 240 | AK7: 242 | AL7: 241 | AM7: 237 | AN7: 240 | AO7: 240 | AP7: 241 | AQ7: 239 | AR7: 241 | AS7: 242 | AT7: 242 | AU7: 241 | AV7: 243 | AW7: 235 | AX7: 241 | AY7: 238 | AZ7: 241 | BA7: 241 | BB7: 241 | BC7: 240 | BD7: 238 | BE7: 241 | BF7: 241 | BG7: 234 | BH7: 242 | BI7: 240 | BJ7: 239 | BK7: 239 | BL7: 239 | BM7: 231 | BN7: 241 | BO7: 241 | BP7: 242 | BQ7: 239 | BR7: 242 | BS7: 243 | BT7: 244 | BU7: 240 | BV7: 240 | BW7: 240 | BX7: 241 | BY7: 239 | BZ7: 242 | CA7: 235 | CB7: 244 | CC7: 232
A8: EndGame-PowerPlan | B8: 2 | C8: Endgame Performance | D8: 14437 | E8: 59.992049 | F8: 0 | G8: Hardware: Independent Flip | H8: 240.64856 | I8: 243.80729 | J8: 190.3719 | K8: 166.26411 | L8: 165.34845 | M8: 77.11884 | N8: 37.459076 | O8: 494.21765 | P8: 4.1554374 | Q8: 0.42744606 | R8: 10.286428 | S8: 0.034635633 | T8: 0.027706587 | V8: 241 | W8: 243 | X8: 241 | Y8: 239 | Z8: 242 | AA8: 243 | AB8: 244 | AC8: 241 | AD8: 242 | AE8: 240 | AF8: 240 | AG8: 239 | AH8: 241 | AI8: 237 | AJ8: 242 | AK8: 243 | AL8: 240 | AM8: 235 | AN8: 240 | AO8: 241 | AP8: 238 | AQ8: 239 | AR8: 241 | AS8: 238 | AT8: 241 | AU8: 239 | AV8: 236 | AW8: 237 | AX8: 240 | AY8: 236 | AZ8: 233 | BA8: 243 | BB8: 235 | BC8: 240 | BD8: 239 | BE8: 242 | BF8: 242 | BG8: 241 | BH8: 242 | BI8: 242 | BJ8: 243 | BK8: 243 | BL8: 243 | BM8: 240 | BN8: 243 | BO8: 235 | BP8: 243 | BQ8: 244 | BR8: 245 | BS8: 243 | BT8: 243 | BU8: 243 | BV8: 243 | BW8: 236 | BX8: 242 | BY8: 243 | BZ8: 242 | CA8: 244 | CB8: 241 | CC8: 240
A9: EndGame-PowerPlan | B9: 3 | C9: Endgame Performance | D9: 14537 | E9: 59.993774 | F9: 0 | G9: Hardware: Independent Flip | H9: 242.30848 | I9: 245.08002 | J9: 193.48527 | K9: 175.28747 | L9: 174.92534 | M9: 94.888064 | N9: 42.084531 | O9: 399.02638 | P9: 4.1269708 | Q9: 0.3949394 | R9: 9.5697165 | S9: 0.027517887 | T9: 0.013757997 | V9: 243 | W9: 246 | X9: 242 | Y9: 243 | Z9: 243 | AA9: 245 | AB9: 243 | AC9: 242 | AD9: 238 | AE9: 242 | AF9: 245 | AG9: 243 | AH9: 242 | AI9: 244 | AJ9: 244 | AK9: 241 | AL9: 233 | AM9: 243 | AN9: 240 | AO9: 243 | AP9: 243 | AQ9: 245 | AR9: 244 | AS9: 243 | AT9: 242 | AU9: 243 | AV9: 243 | AW9: 243 | AX9: 239 | AY9: 243 | AZ9: 244 | BA9: 245 | BB9: 237 | BC9: 243 | BD9: 243 | BE9: 243 | BF9: 243 | BG9: 241 | BH9: 238 | BI9: 243 | BJ9: 243 | BK9: 242 | BL9: 241 | BM9: 242 | BN9: 239 | BO9: 241 | BP9: 244 | BQ9: 245 | BR9: 241 | BS9: 243 | BT9: 246 | BU9: 244 | BV9: 243 | BW9: 242 | BX9: 243 | BY9: 242 | BZ9: 244 | CA9: 242 | CB9: 238 | CC9: 239
A10: EndGame-PowerPlan | B10: 4 | C10: Endgame Performance | D10: 14493 | E10: 59.996426 | F10: 0 | G10: Hardware: Independent Flip | H10: 241.56439 | I10: 244.57053 | J10: 191.16044 | K10: 172.22668 | L10: 172.97194 | M10: 106.17257 | N10: 44.944022 | O10: 396.93566 | P10: 4.139683 | Q10: 0.40300925 | R10: 9.7352683 | S10: 0.013800718 | T10: 0.013799765 | V10: 243 | W10: 240 | X10: 237 | Y10: 239 | Z10: 232 | AA10: 239 | AB10: 243 | AC10: 241 | AD10: 239 | AE10: 241 | AF10: 241 | AG10: 242 | AH10: 245 | AI10: 242 | AJ10: 240 | AK10: 240 | AL10: 241 | AM10: 241 | AN10: 237 | AO10: 243 | AP10: 245 | AQ10: 244 | AR10: 243 | AS10: 241 | AT10: 238 | AU10: 244 | AV10: 240 | AW10: 241 | AX10: 244 | AY10: 240 | AZ10: 242 | BA10: 243 | BB10: 243 | BC10: 244 | BD10: 235 | BE10: 243 | BF10: 246 | BG10: 244 | BH10: 243 | BI10: 242 | BJ10: 244 | BK10: 243 | BL10: 242 | BM10: 244 | BN10: 240 | BO10: 242 | BP10: 244 | BQ10: 243 | BR10: 244 | BS10: 243 | BT10: 244 | BU10: 243 | BV10: 243 | BW10: 242 | BX10: 235 | BY10: 246 | BZ10: 240 | CA10: 239 | CB10: 240 | CC10: 241
A11: EndGame-PowerPlan | B11: 5 | C11: Endgame Performance | D11: 14392 | E11: 59.987511 | F11: 0 | G11: Hardware: Independent Flip | H11: 239.9166 | I11: 243.17292 | J11: 189.21415 | K11: 168.56195 | L11: 168.55303 | M11: 93.831369 | N11: 45.575112 | O11: 507.45966 | P11: 4.168115 | Q11: 0.42080409 | R11: 10.095789 | S11: 0.034743937 | T11: 0.020844914 | V11: 241 | W11: 241 | X11: 243 | Y11: 242 | Z11: 241 | AA11: 237 | AB11: 244 | AC11: 241 | AD11: 243 | AE11: 239 | AF11: 241 | AG11: 240 | AH11: 240 | AI11: 238 | AJ11: 231 | AK11: 232 | AL11: 231 | AM11: 235 | AN11: 233 | AO11: 232 | AP11: 243 | AQ11: 238 | AR11: 242 | AS11: 241 | AT11: 242 | AU11: 242 | AV11: 244 | AW11: 242 | AX11: 239 | AY11: 238 | AZ11: 240 | BA11: 241 | BB11: 240 | BC11: 236 | BD11: 240 | BE11: 242 | BF11: 241 | BG11: 241 | BH11: 240 | BI11: 237 | BJ11: 240 | BK11: 238 | BL11: 242 | BM11: 241 | BN11: 244 | BO11: 242 | BP11: 241 | BQ11: 242 | BR11: 242 | BS11: 239 | BT11: 231 | BU11: 241 | BV11: 245 | BW11: 241 | BX11: 241 | BY11: 245 | BZ11: 243 | CA11: 242 | CB11: 243 | CC11: 235
A12: Prodazin-PowerPlan | B12: 1 | C12: Prodazin Power Plan | D12: 14347 | E12: 60.008809 | F12: 0 | G12: Hardware: Independent Flip | H12: 239.08157 | I12: 242.91891 | J12: 186.44535 | K12: 165.81655 | L12: 162.68009 | M12: 76.910298 | N12: 40.049982 | O12: 406.23984 | P12: 4.1826729 | Q12: 0.44749564 | R12: 10.698796 | S12: 0.027882337 | T12: 0.034850491 | V12: 242 | W12: 244 | X12: 241 | Y12: 242 | Z12: 234 | AA12: 237 | AB12: 242 | AC12: 239 | AD12: 240 | AE12: 243 | AF12: 238 | AG12: 239 | AH12: 237 | AI12: 230 | AJ12: 234 | AK12: 239 | AL12: 241 | AM12: 243 | AN12: 240 | AO12: 239 | AP12: 238 | AQ12: 239 | AR12: 242 | AS12: 238 | AT12: 231 | AU12: 242 | AV12: 241 | AW12: 241 | AX12: 238 | AY12: 239 | AZ12: 240 | BA12: 242 | BB12: 243 | BC12: 240 | BD12: 237 | BE12: 241 | BF12: 241 | BG12: 240 | BH12: 240 | BI12: 240 | BJ12: 241 | BK12: 240 | BL12: 242 | BM12: 239 | BN12: 237 | BO12: 240 | BP12: 241 | BQ12: 238 | BR12: 240 | BS12: 240 | BT12: 240 | BU12: 240 | BV12: 237 | BW12: 234 | BX12: 235 | BY12: 239 | BZ12: 239 | CA12: 241 | CB12: 237 | CC12: 228
A13: Prodazin-PowerPlan | B13: 2 | C13: Prodazin Power Plan | D13: 14355 | E13: 60.009017 | F13: 0 | G13: Hardware: Independent Flip | H13: 239.21405 | I13: 243.13153 | J13: 187.64134 | K13: 166.34469 | L13: 168.12321 | M13: 93.571045 | N13: 38.794424 | O13: 340.79678 | P13: 4.1803565 | Q13: 0.44246484 | R13: 10.584381 | S13: 0.013933398 | T13: 0.013932428 | V13: 241 | W13: 241 | X13: 239 | Y13: 238 | Z13: 239 | AA13: 236 | AB13: 242 | AC13: 239 | AD13: 238 | AE13: 237 | AF13: 240 | AG13: 235 | AH13: 240 | AI13: 238 | AJ13: 242 | AK13: 240 | AL13: 240 | AM13: 241 | AN13: 239 | AO13: 236 | AP13: 242 | AQ13: 238 | AR13: 242 | AS13: 239 | AT13: 239 | AU13: 235 | AV13: 234 | AW13: 240 | AX13: 240 | AY13: 235 | AZ13: 236 | BA13: 241 | BB13: 239 | BC13: 240 | BD13: 238 | BE13: 239 | BF13: 238 | BG13: 240 | BH13: 240 | BI13: 237 | BJ13: 239 | BK13: 240 | BL13: 239 | BM13: 241 | BN13: 242 | BO13: 234 | BP13: 236 | BQ13: 241 | BR13: 242 | BS13: 237 | BT13: 239 | BU13: 241 | BV13: 240 | BW13: 240 | BX13: 242 | BY13: 242 | BZ13: 241 | CA13: 244 | CB13: 242 | CC13: 238
... A196: Velo's-PowerPlan | B196: 5 | C196: Velo's Power Plan | D196: 12535 | E196: 59.998327 | F196: 0 | G196: Hardware: Independent Flip | H196: 208.92249 | I196: 212.72522 | J196: 167.37091 | K196: 147.11554 | L196: 147.2999 | M196: 72.694811 | N196: 38.213883 | O196: 325.26672 | P196: 4.786464 | Q196: 0.44340111 | R196: 9.2636466 | S196: 0.023934897 | T196: 0.039888313 | V196: 210 | W196: 204 | X196: 205 | Y196: 211 | Z196: 210 | AA196: 210 | AB196: 204 | AC196: 211 | AD196: 210 | AE196: 210 | AF196: 209 | AG196: 209 | AH196: 207 | AI196: 206 | AJ196: 211 | AK196: 208 | AL196: 205 | AM196: 208 | AN196: 209 | AO196: 211 | AP196: 210 | AQ196: 210 | AR196: 211 | AS196: 209 | AT196: 209 | AU196: 210 | AV196: 207 | AW196: 211 | AX196: 211 | AY196: 209 | AZ196: 211 | BA196: 211 | BB196: 211 | BC196: 207 | BD196: 207 | BE196: 210 | BF196: 206 | BG196: 209 | BH196: 210 | BI196: 209 | BJ196: 211 | BK196: 211 | BL196: 210 | BM196: 209 | BN196: 212 | BO196: 208 | BP196: 206 | BQ196: 208 | BR196: 210 | BS196: 209 | BT196: 208 | BU196: 207 | BV196: 209 | BW196: 211 | BX196: 209 | BY196: 207 | BZ196: 206 | CA196: 209 | CB196: 209 | CC196: 210

Sheet 4. Statistical Analysis
B2: Statistical Analysis — Per Power Plan (n = 5 repeated captures each)
B3: All statistics below are computed live from Sheet 2 (Raw Data). Delta % and Welch t-test are vs the top-ranked plan.
B5: Best plan (mean Avg FPS) | E5: Worst plan | H5: Best→Worst spread | K5: Run-to-run repeatability | N5: ANOVA across 39 plans
B6: Arsenza-PowerPlan-INTEL — 242.0 FPS | E6: Velo's-PowerPlan — 207.3 FPS | H6: 34.7 FPS (15.1%) | K6: median CV 0.41% · pooled 1.10% | N6: F=51.1, p=3.0e-70 → differences are real
A9: Rank | B9: Power Plan | C9: Type | D9: n | E9: Avg FPS mean | F9: ±SD | G9: CV % | H9: 95% CI ± | I9: Median FPS | J9: 1% Low (P99) | K9: 0.1% Low (P99.9) | L9: 1% Low (worst1%) | M9: 0.1% Low (worst.1%) | N9: Min FPS | O9: Max FPS | P9: Frametime CV % | Q9: Stutter % | R9: Delta vs top (FPS) | S9: Delta vs top % | T9: Welch p vs top | U9: Sig? (p<.05) | V9: Repeat- ability
A10: 1 | B10: Arsenza-PowerPlan-INTEL | C10: community | D10: 5 | E10: =AVERAGE('3. Raw Data'!H2:H6) -> 242.01938 | F10: =STDEV('3. Raw Data'!H2:H6) -> 0.84940431 | G10: =F10/E10*100 -> 0.35096541 | H10: =TINV(0.05,5-1)*F10/SQRT(5) -> 1.0546748 | I10: =AVERAGE('3. Raw Data'!I2:I6) -> 245.89391 | J10: =AVERAGE('3. Raw Data'!J2:J6) -> 192.59228 | K10: =AVERAGE('3. Raw Data'!K2:K6) -> 168.88746 | L10: =AVERAGE('3. Raw Data'!L2:L6) -> 169.62557 | M10: =AVERAGE('3. Raw Data'!M2:M6) -> 88.266121 | N10: =AVERAGE('3. Raw Data'!N2:N6) -> 42.365836 | O10: =AVERAGE('3. Raw Data'!O2:O6) -> 445.8653 | P10: =AVERAGE('3. Raw Data'!R2:R6) -> 10.041674 | Q10: =AVERAGE('3. Raw Data'!S2:S6) -> 0.027540924 | R10: 0 | S10: 0 | T10: ref | U10: top | V10: =IF(G10<1,"Excellent",IF(G10<2,"Good",IF(G10<4,"Fair","Poor"))) -> Excellent
A11: 2 | B11: EndGame-PowerPlan | C11: community | D11: 5 | E11: =AVERAGE('3. Raw Data'!H7:H11) -> 240.81103 | F11: =STDEV('3. Raw Data'!H7:H11) -> 1.1249048 | G11: =F11/E11*100 -> 0.46713175 | H11: =TINV(0.05,5-1)*F11/SQRT(5) -> 1.3967538 | I11: =AVERAGE('3. Raw Data'!I7:I11) -> 243.96547 | J11: =AVERAGE('3. Raw Data'!J7:J11) -> 190.69523 | K11: =AVERAGE('3. Raw Data'!K7:K11) -> 169.79367 | L11: =AVERAGE('3. Raw Data'!L7:L11) -> 170.09047 | M11: =AVERAGE('3. Raw Data'!M7:M11) -> 92.435783 | N11: =AVERAGE('3. Raw Data'!N7:N11) -> 41.631335 | O11: =AVERAGE('3. Raw Data'!O7:O11) -> 444.04801 | P11: =AVERAGE('3. Raw Data'!R7:R11) -> 10.026095 | Q11: =AVERAGE('3. Raw Data'!S7:S11) -> 0.027703691 | R11: =E11-E10 -> -1.2083441 | S11: =(E11-E10)/E10*100 -> -0.49927577 | T11: =TTEST('3. Raw Data'!H7:H11,'3. Raw Data'!H2:H6,2,3) -> 0.094297779 | U11: =IF(T11<0.05,"yes","tie") -> tie | V11: =IF(G11<1,"Excellent",IF(G11<2,"Good",IF(G11<4,"Fair","Poor"))) -> Excellent
A12: 3 | B12: Prodazin-PowerPlan | C12: community | D12: 5 | E12: =AVERAGE('3. Raw Data'!H12:H16) -> 239.2801 | F12: =STDEV('3. Raw Data'!H12:H16) -> 0.43901538 | G12: =F12/E12*100 -> 0.18347342 | H12: =TINV(0.05,5-1)*F12/SQRT(5) -> 0.54510959 | I12: =AVERAGE('3. Raw Data'!I12:I16) -> 242.98055 | J12: =AVERAGE('3. Raw Data'!J12:J16) -> 188.24185 | K12: =AVERAGE('3. Raw Data'!K12:K16) -> 166.80874 | L12: =AVERAGE('3. Raw Data'!L12:L16) -> 167.10006 | M12: =AVERAGE('3. Raw Data'!M12:M16) -> 87.429829 | N12: =AVERAGE('3. Raw Data'!N12:N16) -> 41.269428 | O12: =AVERAGE('3. Raw Data'!O12:O16) -> 404.45648 | P12: =AVERAGE('3. Raw Data'!R12:R16) -> 10.302964 | Q12: =AVERAGE('3. Raw Data'!S12:S16) -> 0.020899767 | R12: =E12-E10 -> -2.7392777 | S12: =(E12-E10)/E10*100 -> -1.1318423 | T12: =TTEST('3. Raw Data'!H12:H16,'3. Raw Data'!H2:H6,2,3) -> 0.0006845598 | U12: =IF(T12<0.05,"yes","tie") -> yes | V12: =IF(G12<1,"Excellent",IF(G12<2,"Good",IF(G12<4,"Fair","Poor"))) -> Excellent
A13: 4 | B13: AMIT-PowerPlan | C13: community | D13: 5 | E13: =AVERAGE('3. Raw Data'!H17:H21) -> 239.03042 | F13: =STDEV('3. Raw Data'!H17:H21) -> 3.1897346 | G13: =F13/E13*100 -> 1.3344471 | H13: =TINV(0.05,5-1)*F13/SQRT(5) -> 3.9605786 | I13: =AVERAGE('3. Raw Data'!I17:I21) -> 243.18907 | J13: =AVERAGE('3. Raw Data'!J17:J21) -> 185.69308 | K13: =AVERAGE('3. Raw Data'!K17:K21) -> 150.28908 | L13: =AVERAGE('3. Raw Data'!L17:L21) -> 153.74556 | M13: =AVERAGE('3. Raw Data'!M17:M21) -> 78.829477 | N13: =AVERAGE('3. Raw Data'!N17:N21) -> 40.681634 | O13: =AVERAGE('3. Raw Data'!O17:O21) -> 388.98189 | P13: =AVERAGE('3. Raw Data'!R17:R21) -> 11.183231 | Q13: =AVERAGE('3. Raw Data'!S17:S21) -> 0.057109888 | R13: =E13-E10 -> -2.9889607 | S13: =(E13-E10)/E10*100 -> -1.2350088 | T13: =TTEST('3. Raw Data'!H17:H21,'3. Raw Data'!H2:H6,2,3) -> 0.10417033 | U13: =IF(T13<0.05,"yes","tie") -> tie | V13: =IF(G13<1,"Excellent",IF(G13<2,"Good",IF(G13<4,"Fair","Poor"))) -> Good
A14: 5 | B14: LLG-CERTIFIED-FOR-PARKING+E-CORES-FIX-PowerPlan | C14: community | D14: 5 | E14: =AVERAGE('3. Raw Data'!H22:H26) -> 238.60991 | F14: =STDEV('3. Raw Data'!H22:H26) -> 0.83261149 | G14: =F14/E14*100 -> 0.34894254 | H14: =TINV(0.05,5-1)*F14/SQRT(5) -> 1.0338237 | I14: =AVERAGE('3. Raw Data'!I22:I26) -> 242.39851 | J14: =AVERAGE('3. Raw Data'!J22:J26) -> 191.15592 | K14: =AVERAGE('3. Raw Data'!K22:K26) -> 170.36294 | L14: =AVERAGE('3. Raw Data'!L22:L26) -> 172.49631 | M14: =AVERAGE('3. Raw Data'!M22:M26) -> 96.801544 | N14: =AVERAGE('3. Raw Data'!N22:N26) -> 40.501651 | O14: =AVERAGE('3. Raw Data'!O22:O26) -> 424.11565 | P14: =AVERAGE('3. Raw Data'!R22:R26) -> 9.6035115 | Q14: =AVERAGE('3. Raw Data'!S22:S26) -> 0.01816841 | R14: =E14-E10 -> -3.4094651 | S14: =(E14-E10)/E10*100 -> -1.4087571 | T14: =TTEST('3. Raw Data'!H22:H26,'3. Raw Data'!H2:H6,2,3) -> 0.00020734856 | U14: =IF(T14<0.05,"yes","tie") -> yes | V14: =IF(G14<1,"Excellent",IF(G14<2,"Good",IF(G14<4,"Fair","Poor"))) -> Excellent
A15: 6 | B15: Synez-PowerPlan | C15: community | D15: 5 | E15: =AVERAGE('3. Raw Data'!H27:H31) -> 237.93382 | F15: =STDEV('3. Raw Data'!H27:H31) -> 5.1260421 | G15: =F15/E15*100 -> 2.1543983 | H15: =TINV(0.05,5-1)*F15/SQRT(5) -> 6.3648219 | I15: =AVERAGE('3. Raw Data'!I27:I31) -> 241.73516 | J15: =AVERAGE('3. Raw Data'!J27:J31) -> 187.88239 | K15: =AVERAGE('3. Raw Data'!K27:K31) -> 166.44739 | L15: =AVERAGE('3. Raw Data'!L27:L31) -> 168.44024 | M15: =AVERAGE('3. Raw Data'!M27:M31) -> 96.689541 | N15: =AVERAGE('3. Raw Data'!N27:N31) -> 42.085042 | O15: =AVERAGE('3. Raw Data'!O27:O31) -> 443.2537 | P15: =AVERAGE('3. Raw Data'!R27:R31) -> 9.9330218 | Q15: =AVERAGE('3. Raw Data'!S27:S31) -> 0.015403053 | R15: =E15-E10 -> -4.0855612 | S15: =(E15-E10)/E10*100 -> -1.6881132 | T15: =TTEST('3. Raw Data'!H27:H31,'3. Raw Data'!H2:H6,2,3) -> 0.14979661 | U15: =IF(T15<0.05,"yes","tie") -> tie | V15: =IF(G15<1,"Excellent",IF(G15<2,"Good",IF(G15<4,"Fair","Poor"))) -> Fair
A16: 7 | B16: Revision-PowerPlan | C16: community | D16: 5 | E16: =AVERAGE('3. Raw Data'!H32:H36) -> 237.23655 | F16: =STDEV('3. Raw Data'!H32:H36) -> 0.8764072 | G16: =F16/E16*100 -> 0.36942335 | H16: =TINV(0.05,5-1)*F16/SQRT(5) -> 1.0882033 | I16: =AVERAGE('3. Raw Data'!I32:I36) -> 241.34605 | J16: =AVERAGE('3. Raw Data'!J32:J36) -> 187.49343 | K16: =AVERAGE('3. Raw Data'!K32:K36) -> 163.64862 | L16: =AVERAGE('3. Raw Data'!L32:L36) -> 166.35987 | M16: =AVERAGE('3. Raw Data'!M32:M36) -> 88.816008 | N16: =AVERAGE('3. Raw Data'!N32:N36) -> 42.629984 | O16: =AVERAGE('3. Raw Data'!O32:O36) -> 409.09491 | P16: =AVERAGE('3. Raw Data'!R32:R36) -> 10.151706 | Q16: =AVERAGE('3. Raw Data'!S32:S36) -> 0.019653879 | R16: =E16-E10 -> -4.7828315 | S16: =(E16-E10)/E10*100 -> -1.9762184 | T16: =TTEST('3. Raw Data'!H32:H36,'3. Raw Data'!H2:H6,2,3) -> 2.2681885e-05 | U16: =IF(T16<0.05,"yes","tie") -> yes | V16: =IF(G16<1,"Excellent",IF(G16<2,"Good",IF(G16<4,"Fair","Poor"))) -> Excellent
A17: 8 | B17: Reticle-PowerPlan | C17: community | D17: 5 | E17: =AVERAGE('3. Raw Data'!H37:H41) -> 236.74462 | F17: =STDEV('3. Raw Data'!H37:H41) -> 3.9418997 | G17: =F17/E17*100 -> 1.665043 | H17: =TINV(0.05,5-1)*F17/SQRT(5) -> 4.894515 | I17: =AVERAGE('3. Raw Data'!I37:I41) -> 241.32191 | J17: =AVERAGE('3. Raw Data'!J37:J41) -> 179.84576 | K17: =AVERAGE('3. Raw Data'!K37:K41) -> 142.64201 | L17: =AVERAGE('3. Raw Data'!L37:L41) -> 147.49031 | M17: =AVERAGE('3. Raw Data'!M37:M41) -> 73.813243 | N17: =AVERAGE('3. Raw Data'!N37:N41) -> 37.265944 | O17: =AVERAGE('3. Raw Data'!O37:O41) -> 424.14145 | P17: =AVERAGE('3. Raw Data'!R37:R41) -> 12.005699 | Q17: =AVERAGE('3. Raw Data'!S37:S41) -> 0.054989317 | R17: =E17-E10 -> -5.2747549 | S17: =(E17-E10)/E10*100 -> -2.1794763 | T17: =TTEST('3. Raw Data'!H37:H41,'3. Raw Data'!H2:H6,2,3) -> 0.038616533 | U17: =IF(T17<0.05,"yes","tie") -> yes | V17: =IF(G17<1,"Excellent",IF(G17<2,"Good",IF(G17<4,"Fair","Poor"))) -> Good
A18: 9 | B18: LLG-CERTIFIED-FOR-NON-K-CPUs-PowerPlan | C18: community | D18: 5 | E18: =AVERAGE('3. Raw Data'!H42:H46) -> 236.63059 | F18: =STDEV('3. Raw Data'!H42:H46) -> 4.8998958 | G18: =F18/E18*100 -> 2.0706942 | H18: =TINV(0.05,5-1)*F18/SQRT(5) -> 6.0840242 | I18: =AVERAGE('3. Raw Data'!I42:I46) -> 239.95978 | J18: =AVERAGE('3. Raw Data'!J42:J46) -> 189.46507 | K18: =AVERAGE('3. Raw Data'!K42:K46) -> 169.26683 | L18: =AVERAGE('3. Raw Data'!L42:L46) -> 170.36306 | M18: =AVERAGE('3. Raw Data'!M42:M46) -> 100.57645 | N18: =AVERAGE('3. Raw Data'!N42:N46) -> 40.972504 | O18: =AVERAGE('3. Raw Data'!O42:O46) -> 441.71732 | P18: =AVERAGE('3. Raw Data'!R42:R46) -> 9.8052149 | Q18: =AVERAGE('3. Raw Data'!S42:S46) -> 0.012629624 | R18: =E18-E10 -> -5.3887928 | S18: =(E18-E10)/E10*100 -> -2.2265956 | T18: =TTEST('3. Raw Data'!H42:H46,'3. Raw Data'!H2:H6,2,3) -> 0.06892231 | U18: =IF(T18<0.05,"yes","tie") -> tie | V18: =IF(G18<1,"Excellent",IF(G18<2,"Good",IF(G18<4,"Fair","Poor"))) -> Fair
A19: 10 | B19: CactusOS-PowerPlan | C19: community | D19: 5 | E19: =AVERAGE('3. Raw Data'!H47:H51) -> 236.3909 | F19: =STDEV('3. Raw Data'!H47:H51) -> 2.5878742 | G19: =F19/E19*100 -> 1.0947436 | H19: =TINV(0.05,5-1)*F19/SQRT(5) -> 3.2132703 | I19: =AVERAGE('3. Raw Data'!I47:I51) -> 240.57106 | J19: =AVERAGE('3. Raw Data'!J47:J51) -> 185.27753 | K19: =AVERAGE('3. Raw Data'!K47:K51) -> 162.83044 | L19: =AVERAGE('3. Raw Data'!L47:L51) -> 164.04516 | M19: =AVERAGE('3. Raw Data'!M47:M51) -> 88.574928 | N19: =AVERAGE('3. Raw Data'!N47:N51) -> 43.133747 | O19: =AVERAGE('3. Raw Data'!O47:O51) -> 428.28952 | P19: =AVERAGE('3. Raw Data'!R47:R51) -> 10.353332 | Q19: =AVERAGE('3. Raw Data'!S47:S51) -> 0.025367149 | R19: =E19-E10 -> -5.6284784 | S19: =(E19-E10)/E10*100 -> -2.3256313 | T19: =TTEST('3. Raw Data'!H47:H51,'3. Raw Data'!H2:H6,2,3) -> 0.0061761424 | U19: =IF(T19<0.05,"yes","tie") -> yes | V19: =IF(G19<1,"Excellent",IF(G19<2,"Good",IF(G19<4,"Fair","Poor"))) -> Good
A20: 11 | B20: Imribiy-2026-PowerPlan | C20: community | D20: 5 | E20: =AVERAGE('3. Raw Data'!H52:H56) -> 235.3278 | F20: =STDEV('3. Raw Data'!H52:H56) -> 4.3645692 | G20: =F20/E20*100 -> 1.8546764 | H20: =TINV(0.05,5-1)*F20/SQRT(5) -> 5.4193284 | I20: =AVERAGE('3. Raw Data'!I52:I56) -> 238.53305 | J20: =AVERAGE('3. Raw Data'!J52:J56) -> 188.01593 | K20: =AVERAGE('3. Raw Data'!K52:K56) -> 167.10595 | L20: =AVERAGE('3. Raw Data'!L52:L56) -> 168.21306 | M20: =AVERAGE('3. Raw Data'!M52:M56) -> 93.661291 | N20: =AVERAGE('3. Raw Data'!N52:N56) -> 40.301962 | O20: =AVERAGE('3. Raw Data'!O52:O56) -> 410.12369 | P20: =AVERAGE('3. Raw Data'!R52:R56) -> 10.079241 | Q20: =AVERAGE('3. Raw Data'!S52:S56) -> 0.017061307 | R20: =E20-E10 -> -6.6915776 | S20: =(E20-E10)/E10*100 -> -2.7648933 | T20: =TTEST('3. Raw Data'!H52:H56,'3. Raw Data'!H2:H6,2,3) -> 0.025188675 | U20: =IF(T20<0.05,"yes","tie") -> yes | V20: =IF(G20<1,"Excellent",IF(G20<2,"Good",IF(G20<4,"Fair","Poor"))) -> Good
A21: 12 | B21: FPSHEAVEN2026-PowerPlan | C21: community | D21: 5 | E21: =AVERAGE('3. Raw Data'!H57:H61) -> 234.92248 | F21: =STDEV('3. Raw Data'!H57:H61) -> 4.1012522 | G21: =F21/E21*100 -> 1.7457896 | H21: =TINV(0.05,5-1)*F21/SQRT(5) -> 5.0923772 | I21: =AVERAGE('3. Raw Data'!I57:I61) -> 238.80134 | J21: =AVERAGE('3. Raw Data'!J57:J61) -> 183.20849 | K21: =AVERAGE('3. Raw Data'!K57:K61) -> 161.96029 | L21: =AVERAGE('3. Raw Data'!L57:L61) -> 162.37187 | M21: =AVERAGE('3. Raw Data'!M57:M61) -> 87.06541 | N21: =AVERAGE('3. Raw Data'!N57:N61) -> 40.262212 | O21: =AVERAGE('3. Raw Data'!O57:O61) -> 371.93747 | P21: =AVERAGE('3. Raw Data'!R57:R61) -> 11.125119 | Q21: =AVERAGE('3. Raw Data'!S57:S61) -> 0.01989454 | R21: =E21-E10 -> -7.0969011 | S21: =(E21-E10)/E10*100 -> -2.932369 | T21: =TTEST('3. Raw Data'!H57:H61,'3. Raw Data'!H2:H6,2,3) -> 0.016587534 | U21: =IF(T21<0.05,"yes","tie") -> yes | V21: =IF(G21<1,"Excellent",IF(G21<2,"Good",IF(G21<4,"Fair","Poor"))) -> Good
A22: 13 | B22: Mitstas-PowerPlan | C22: community | D22: 5 | E22: =AVERAGE('3. Raw Data'!H62:H66) -> 233.13345 | F22: =STDEV('3. Raw Data'!H62:H66) -> 4.5383495 | G22: =F22/E22*100 -> 1.9466746 | H22: =TINV(0.05,5-1)*F22/SQRT(5) -> 5.6351051 | I22: =AVERAGE('3. Raw Data'!I62:I66) -> 237.52015 | J22: =AVERAGE('3. Raw Data'!J62:J66) -> 178.45514 | K22: =AVERAGE('3. Raw Data'!K62:K66) -> 152.9828 | L22: =AVERAGE('3. Raw Data'!L62:L66) -> 153.36537 | M22: =AVERAGE('3. Raw Data'!M62:M66) -> 69.928381 | N22: =AVERAGE('3. Raw Data'!N62:N66) -> 38.795007 | O22: =AVERAGE('3. Raw Data'!O62:O66) -> 361.56681 | P22: =AVERAGE('3. Raw Data'!R62:R66) -> 11.68365 | Q22: =AVERAGE('3. Raw Data'!S62:S66) -> 0.034558719 | R22: =E22-E10 -> -8.8859333 | S22: =(E22-E10)/E10*100 -> -3.6715792 | T22: =TTEST('3. Raw Data'!H62:H66,'3. Raw Data'!H2:H6,2,3) -> 0.010877736 | U22: =IF(T22<0.05,"yes","tie") -> yes | V22: =IF(G22<1,"Excellent",IF(G22<2,"Good",IF(G22<4,"Fair","Poor"))) -> Good
A23: 14 | B23: Bitsum-Highest-Performance-PowerPlan | C23: community | D23: 5 | E23: =AVERAGE('3. Raw Data'!H67:H71) -> 232.85436 | F23: =STDEV('3. Raw Data'!H67:H71) -> 4.0578641 | G23: =F23/E23*100 -> 1.7426619 | H23: =TINV(0.05,5-1)*F23/SQRT(5) -> 5.0385038 | I23: =AVERAGE('3. Raw Data'!I67:I71) -> 237.58109 | J23: =AVERAGE('3. Raw Data'!J67:J71) -> 177.47692 | K23: =AVERAGE('3. Raw Data'!K67:K71) -> 128.36076 | L23: =AVERAGE('3. Raw Data'!L67:L71) -> 135.62531 | M23: =AVERAGE('3. Raw Data'!M67:M71) -> 50.441774 | N23: =AVERAGE('3. Raw Data'!N67:N71) -> 31.741866 | O23: =AVERAGE('3. Raw Data'!O67:O71) -> 439.83507 | P23: =AVERAGE('3. Raw Data'!R67:R71) -> 12.94782 | Q23: =AVERAGE('3. Raw Data'!S67:S71) -> 0.071340715 | R23: =E23-E10 -> -9.1650203 | S23: =(E23-E10)/E10*100 -> -3.7868952 | T23: =TTEST('3. Raw Data'!H67:H71,'3. Raw Data'!H2:H6,2,3) -> 0.0062656162 | U23: =IF(T23<0.05,"yes","tie") -> yes | V23: =IF(G23<1,"Excellent",IF(G23<2,"Good",IF(G23<4,"Fair","Poor"))) -> Good
A24: 15 | B24: AutoOS-PowerPlan | C24: community | D24: 5 | E24: =AVERAGE('3. Raw Data'!H72:H76) -> 231.27971 | F24: =STDEV('3. Raw Data'!H72:H76) -> 0.73806796 | G24: =F24/E24*100 -> 0.31912353 | H24: =TINV(0.05,5-1)*F24/SQRT(5) -> 0.91643242 | I24: =AVERAGE('3. Raw Data'!I72:I76) -> 234.31963 | J24: =AVERAGE('3. Raw Data'!J72:J76) -> 178.72501 | K24: =AVERAGE('3. Raw Data'!K72:K76) -> 158.60058 | L24: =AVERAGE('3. Raw Data'!L72:L76) -> 158.11645 | M24: =AVERAGE('3. Raw Data'!M72:M76) -> 86.090037 | N24: =AVERAGE('3. Raw Data'!N72:N76) -> 42.242147 | O24: =AVERAGE('3. Raw Data'!O72:O76) -> 409.86668 | P24: =AVERAGE('3. Raw Data'!R72:R76) -> 11.713901 | Q24: =AVERAGE('3. Raw Data'!S72:S76) -> 0.027368041 | R24: =E24-E10 -> -10.739671 | S24: =(E24-E10)/E10*100 -> -4.4375252 | T24: =TTEST('3. Raw Data'!H72:H76,'3. Raw Data'!H2:H6,2,3) -> 3.1227676e-08 | U24: =IF(T24<0.05,"yes","tie") -> yes | V24: =IF(G24<1,"Excellent",IF(G24<2,"Good",IF(G24<4,"Fair","Poor"))) -> Excellent
A25: 16 | B25: RIP-PowerPlan | C25: community | D25: 5 | E25: =AVERAGE('3. Raw Data'!H77:H81) -> 230.79199 | F25: =STDEV('3. Raw Data'!H77:H81) -> 4.6335091 | G25: =F25/E25*100 -> 2.0076559 | H25: =TINV(0.05,5-1)*F25/SQRT(5) -> 5.7532614 | I25: =AVERAGE('3. Raw Data'!I77:I81) -> 234.36424 | J25: =AVERAGE('3. Raw Data'!J77:J81) -> 178.69032 | K25: =AVERAGE('3. Raw Data'!K77:K81) -> 156.00137 | L25: =AVERAGE('3. Raw Data'!L77:L81) -> 156.72327 | M25: =AVERAGE('3. Raw Data'!M77:M81) -> 83.019994 | N25: =AVERAGE('3. Raw Data'!N77:N81) -> 41.048624 | O25: =AVERAGE('3. Raw Data'!O77:O81) -> 388.43584 | P25: =AVERAGE('3. Raw Data'!R77:R81) -> 10.968093 | Q25: =AVERAGE('3. Raw Data'!S77:S81) -> 0.024661286 | R25: =E25-E10 -> -11.227385 | S25: =(E25-E10)/E10*100 -> -4.6390439 | T25: =TTEST('3. Raw Data'!H77:H81,'3. Raw Data'!H2:H6,2,3) -> 0.0049608019 | U25: =IF(T25<0.05,"yes","tie") -> yes | V25: =IF(G25<1,"Excellent",IF(G25<2,"Good",IF(G25<4,"Fair","Poor"))) -> Fair
A26: 17 | B26: Slower-PowerPlan | C26: community | D26: 5 | E26: =AVERAGE('3. Raw Data'!H82:H86) -> 230.45211 | F26: =STDEV('3. Raw Data'!H82:H86) -> 0.96552921 | G26: =F26/E26*100 -> 0.41897174 | H26: =TINV(0.05,5-1)*F26/SQRT(5) -> 1.1988629 | I26: =AVERAGE('3. Raw Data'!I82:I86) -> 233.85131 | J26: =AVERAGE('3. Raw Data'!J82:J86) -> 176.8728 | K26: =AVERAGE('3. Raw Data'!K82:K86) -> 155.95638 | L26: =AVERAGE('3. Raw Data'!L82:L86) -> 153.18878 | M26: =AVERAGE('3. Raw Data'!M82:M86) -> 76.946362 | N26: =AVERAGE('3. Raw Data'!N82:N86) -> 34.965217 | O26: =AVERAGE('3. Raw Data'!O82:O86) -> 432.67384 | P26: =AVERAGE('3. Raw Data'!R82:R86) -> 12.392284 | Q26: =AVERAGE('3. Raw Data'!S82:S86) -> 0.018781096 | R26: =E26-E10 -> -11.56727 | S26: =(E26-E10)/E10*100 -> -4.7794809 | T26: =TTEST('3. Raw Data'!H82:H86,'3. Raw Data'!H2:H6,2,3) -> 4.746886e-08 | U26: =IF(T26<0.05,"yes","tie") -> yes | V26: =IF(G26<1,"Excellent",IF(G26<2,"Good",IF(G26<4,"Fair","Poor"))) -> Excellent
A27: 18 | B27: BEYOND-PERFORMANCE-AMD-INTEL-V1-PowerPlan | C27: community | D27: 5 | E27: =AVERAGE('3. Raw Data'!H87:H91) -> 230.44443 | F27: =STDEV('3. Raw Data'!H87:H91) -> 0.43194651 | G27: =F27/E27*100 -> 0.18744064 | H27: =TINV(0.05,5-1)*F27/SQRT(5) -> 0.53633243 | I27: =AVERAGE('3. Raw Data'!I87:I91) -> 233.19412 | J27: =AVERAGE('3. Raw Data'!J87:J91) -> 178.87812 | K27: =AVERAGE('3. Raw Data'!K87:K91) -> 158.62063 | L27: =AVERAGE('3. Raw Data'!L87:L91) -> 158.34293 | M27: =AVERAGE('3. Raw Data'!M87:M91) -> 83.458377 | N27: =AVERAGE('3. Raw Data'!N87:N91) -> 39.570324 | O27: =AVERAGE('3. Raw Data'!O87:O91) -> 388.85472 | P27: =AVERAGE('3. Raw Data'!R87:R91) -> 11.847604 | Q27: =AVERAGE('3. Raw Data'!S87:S91) -> 0.026043824 | R27: =E27-E10 -> -11.574945 | S27: =(E27-E10)/E10*100 -> -4.7826522 | T27: =TTEST('3. Raw Data'!H87:H91,'3. Raw Data'!H2:H6,2,3) -> 1.8581105e-07 | U27: =IF(T27<0.05,"yes","tie") -> yes | V27: =IF(G27<1,"Excellent",IF(G27<2,"Good",IF(G27<4,"Fair","Poor"))) -> Excellent
A28: 19 | B28: Iris-PowerPlan | C28: community | D28: 5 | E28: =AVERAGE('3. Raw Data'!H92:H96) -> 229.91298 | F28: =STDEV('3. Raw Data'!H92:H96) -> 2.8062895 | G28: =F28/E28*100 -> 1.2205877 | H28: =TINV(0.05,5-1)*F28/SQRT(5) -> 3.4844686 | I28: =AVERAGE('3. Raw Data'!I92:I96) -> 232.26522 | J28: =AVERAGE('3. Raw Data'!J92:J96) -> 180.61216 | K28: =AVERAGE('3. Raw Data'!K92:K96) -> 160.45526 | L28: =AVERAGE('3. Raw Data'!L92:L96) -> 160.52342 | M28: =AVERAGE('3. Raw Data'!M92:M96) -> 90.098929 | N28: =AVERAGE('3. Raw Data'!N92:N96) -> 40.861861 | O28: =AVERAGE('3. Raw Data'!O92:O96) -> 396.61208 | P28: =AVERAGE('3. Raw Data'!R92:R96) -> 10.736453 | Q28: =AVERAGE('3. Raw Data'!S92:S96) -> 0.020298997 | R28: =E28-E10 -> -12.106398 | S28: =(E28-E10)/E10*100 -> -5.0022432 | T28: =TTEST('3. Raw Data'!H92:H96,'3. Raw Data'!H2:H6,2,3) -> 0.00033572063 | U28: =IF(T28<0.05,"yes","tie") -> yes | V28: =IF(G28<1,"Excellent",IF(G28<2,"Good",IF(G28<4,"Fair","Poor"))) -> Good
A29: 20 | B29: Sapphire-PowerPlan | C29: community | D29: 5 | E29: =AVERAGE('3. Raw Data'!H97:H101) -> 229.64507 | F29: =STDEV('3. Raw Data'!H97:H101) -> 0.94662523 | G29: =F29/E29*100 -> 0.4122123 | H29: =TINV(0.05,5-1)*F29/SQRT(5) -> 1.1753905 | I29: =AVERAGE('3. Raw Data'!I97:I101) -> 232.97048 | J29: =AVERAGE('3. Raw Data'!J97:J101) -> 175.5231 | K29: =AVERAGE('3. Raw Data'!K97:K101) -> 155.38403 | L29: =AVERAGE('3. Raw Data'!L97:L101) -> 154.89029 | M29: =AVERAGE('3. Raw Data'!M97:M101) -> 84.417388 | N29: =AVERAGE('3. Raw Data'!N97:N101) -> 40.045927 | O29: =AVERAGE('3. Raw Data'!O97:O101) -> 460.02852 | P29: =AVERAGE('3. Raw Data'!R97:R101) -> 11.567868 | Q29: =AVERAGE('3. Raw Data'!S97:S101) -> 0.023246777 | R29: =E29-E10 -> -12.374307 | S29: =(E29-E10)/E10*100 -> -5.1129408 | T29: =TTEST('3. Raw Data'!H97:H101,'3. Raw Data'!H2:H6,2,3) -> 2.438736e-08 | U29: =IF(T29<0.05,"yes","tie") -> yes | V29: =IF(G29<1,"Excellent",IF(G29<2,"Good",IF(G29<4,"Fair","Poor"))) -> Excellent
A30: 21 | B30: Sazinho-PowerPlan | C30: community | D30: 5 | E30: =AVERAGE('3. Raw Data'!H102:H106) -> 229.08121 | F30: =STDEV('3. Raw Data'!H102:H106) -> 0.92931351 | G30: =F30/E30*100 -> 0.40566991 | H30: =TINV(0.05,5-1)*F30/SQRT(5) -> 1.1538951 | I30: =AVERAGE('3. Raw Data'!I102:I106) -> 232.40191 | J30: =AVERAGE('3. Raw Data'!J102:J106) -> 174.21624 | K30: =AVERAGE('3. Raw Data'!K102:K106) -> 152.88279 | L30: =AVERAGE('3. Raw Data'!L102:L106) -> 153.48255 | M30: =AVERAGE('3. Raw Data'!M102:M106) -> 82.339467 | N30: =AVERAGE('3. Raw Data'!N102:N106) -> 40.199386 | O30: =AVERAGE('3. Raw Data'!O102:O106) -> 436.10801 | P30: =AVERAGE('3. Raw Data'!R102:R106) -> 11.638492 | Q30: =AVERAGE('3. Raw Data'!S102:S106) -> 0.029121764 | R30: =E30-E10 -> -12.938173 | S30: =(E30-E10)/E10*100 -> -5.3459243 | T30: =TTEST('3. Raw Data'!H102:H106,'3. Raw Data'!H2:H6,2,3) -> 1.5182863e-08 | U30: =IF(T30<0.05,"yes","tie") -> yes | V30: =IF(G30<1,"Excellent",IF(G30<2,"Good",IF(G30<4,"Fair","Poor"))) -> Excellent
A31: 22 | B31: JokrOS-PowerPlan | C31: community | D31: 5 | E31: =AVERAGE('3. Raw Data'!H107:H111) -> 228.55973 | F31: =STDEV('3. Raw Data'!H107:H111) -> 0.66886176 | G31: =F31/E31*100 -> 0.292642 | H31: =TINV(0.05,5-1)*F31/SQRT(5) -> 0.83050156 | I31: =AVERAGE('3. Raw Data'!I107:I111) -> 230.97481 | J31: =AVERAGE('3. Raw Data'!J107:J111) -> 178.33864 | K31: =AVERAGE('3. Raw Data'!K107:K111) -> 158.45048 | L31: =AVERAGE('3. Raw Data'!L107:L111) -> 159.37949 | M31: =AVERAGE('3. Raw Data'!M107:M111) -> 89.524981 | N31: =AVERAGE('3. Raw Data'!N107:N111) -> 40.472559 | O31: =AVERAGE('3. Raw Data'!O107:O111) -> 406.00412 | P31: =AVERAGE('3. Raw Data'!R107:R111) -> 11.544878 | Q31: =AVERAGE('3. Raw Data'!S107:S111) -> 0.020432261 | R31: =E31-E10 -> -13.459649 | S31: =(E31-E10)/E10*100 -> -5.5613931 | T31: =TTEST('3. Raw Data'!H107:H111,'3. Raw Data'!H2:H6,2,3) -> 6.5259005e-09 | U31: =IF(T31<0.05,"yes","tie") -> yes | V31: =IF(G31<1,"Excellent",IF(G31<2,"Good",IF(G31<4,"Fair","Poor"))) -> Excellent
A32: 23 | B32: Khorvie-PowerPlan | C32: community | D32: 5 | E32: =AVERAGE('3. Raw Data'!H112:H116) -> 228.4636 | F32: =STDEV('3. Raw Data'!H112:H116) -> 0.26452956 | G32: =F32/E32*100 -> 0.1157863 | H32: =TINV(0.05,5-1)*F32/SQRT(5) -> 0.32845683 | I32: =AVERAGE('3. Raw Data'!I112:I116) -> 230.66194 | J32: =AVERAGE('3. Raw Data'!J112:J116) -> 179.16336 | K32: =AVERAGE('3. Raw Data'!K112:K116) -> 161.42652 | L32: =AVERAGE('3. Raw Data'!L112:L116) -> 161.27114 | M32: =AVERAGE('3. Raw Data'!M112:M116) -> 93.846199 | N32: =AVERAGE('3. Raw Data'!N112:N116) -> 40.882621 | O32: =AVERAGE('3. Raw Data'!O112:O116) -> 429.85598 | P32: =AVERAGE('3. Raw Data'!R112:R116) -> 11.463381 | Q32: =AVERAGE('3. Raw Data'!S112:S116) -> 0.014590143 | R32: =E32-E10 -> -13.555779 | S32: =(E32-E10)/E10*100 -> -5.601113 | T32: =TTEST('3. Raw Data'!H112:H116,'3. Raw Data'!H2:H6,2,3) -> 7.0234944e-07 | U32: =IF(T32<0.05,"yes","tie") -> yes | V32: =IF(G32<1,"Excellent",IF(G32<2,"Good",IF(G32<4,"Fair","Poor"))) -> Excellent
A33: 24 | B33: GALA'S-Ultimate-Performance-AMD-PowerPlan | C33: community | D33: 5 | E33: =AVERAGE('3. Raw Data'!H117:H121) -> 228.07913 | F33: =STDEV('3. Raw Data'!H117:H121) -> 0.19792831 | G33: =F33/E33*100 -> 0.086780545 | H33: =TINV(0.05,5-1)*F33/SQRT(5) -> 0.24576046 | I33: =AVERAGE('3. Raw Data'!I117:I121) -> 230.41228 | J33: =AVERAGE('3. Raw Data'!J117:J121) -> 178.3592 | K33: =AVERAGE('3. Raw Data'!K117:K121) -> 161.94819 | L33: =AVERAGE('3. Raw Data'!L117:L121) -> 161.34229 | M33: =AVERAGE('3. Raw Data'!M117:M121) -> 94.153727 | N33: =AVERAGE('3. Raw Data'!N117:N121) -> 48.69173 | O33: =AVERAGE('3. Raw Data'!O117:O121) -> 384.57381 | P33: =AVERAGE('3. Raw Data'!R117:R121) -> 11.32876 | Q33: =AVERAGE('3. Raw Data'!S117:S121) -> 0.024851358 | R33: =E33-E10 -> -13.940248 | S33: =(E33-E10)/E10*100 -> -5.7599719 | T33: =TTEST('3. Raw Data'!H117:H121,'3. Raw Data'!H2:H6,2,3) -> 1.257804e-06 | U33: =IF(T33<0.05,"yes","tie") -> yes | V33: =IF(G33<1,"Excellent",IF(G33<2,"Good",IF(G33<4,"Fair","Poor"))) -> Excellent
A34: 25 | B34: Jackpot2026-PowerPlan | C34: community | D34: 5 | E34: =AVERAGE('3. Raw Data'!H122:H126) -> 227.86705 | F34: =STDEV('3. Raw Data'!H122:H126) -> 0.44216448 | G34: =F34/E34*100 -> 0.19404494 | H34: =TINV(0.05,5-1)*F34/SQRT(5) -> 0.54901972 | I34: =AVERAGE('3. Raw Data'!I122:I126) -> 230.11197 | J34: =AVERAGE('3. Raw Data'!J122:J126) -> 178.1483 | K34: =AVERAGE('3. Raw Data'!K122:K126) -> 158.92654 | L34: =AVERAGE('3. Raw Data'!L122:L126) -> 160.60692 | M34: =AVERAGE('3. Raw Data'!M122:M126) -> 94.994295 | N34: =AVERAGE('3. Raw Data'!N122:N126) -> 39.844417 | O34: =AVERAGE('3. Raw Data'!O122:O126) -> 392.74053 | P34: =AVERAGE('3. Raw Data'!R122:R126) -> 11.5006 | Q34: =AVERAGE('3. Raw Data'!S122:S126) -> 0.010246248 | R34: =E34-E10 -> -14.152332 | S34: =(E34-E10)/E10*100 -> -5.847603 | T34: =TTEST('3. Raw Data'!H122:H126,'3. Raw Data'!H2:H6,2,3) -> 4.8949753e-08 | U34: =IF(T34<0.05,"yes","tie") -> yes | V34: =IF(G34<1,"Excellent",IF(G34<2,"Good",IF(G34<4,"Fair","Poor"))) -> Excellent
A35: 26 | B35: Arsezna-PowerPlan-ALL-CPU | C35: community | D35: 5 | E35: =AVERAGE('3. Raw Data'!H127:H131) -> 227.5122 | F35: =STDEV('3. Raw Data'!H127:H131) -> 5.6175673 | G35: =F35/E35*100 -> 2.4691279 | H35: =TINV(0.05,5-1)*F35/SQRT(5) -> 6.9751311 | I35: =AVERAGE('3. Raw Data'!I127:I131) -> 230.38295 | J35: =AVERAGE('3. Raw Data'!J127:J131) -> 177.3939 | K35: =AVERAGE('3. Raw Data'!K127:K131) -> 156.12007 | L35: =AVERAGE('3. Raw Data'!L127:L131) -> 157.28115 | M35: =AVERAGE('3. Raw Data'!M127:M131) -> 85.552794 | N35: =AVERAGE('3. Raw Data'!N127:N131) -> 39.494379 | O35: =AVERAGE('3. Raw Data'!O127:O131) -> 404.46508 | P35: =AVERAGE('3. Raw Data'!R127:R131) -> 10.973297 | Q35: =AVERAGE('3. Raw Data'!S127:S131) -> 0.019078111 | R35: =E35-E10 -> -14.507174 | S35: =(E35-E10)/E10*100 -> -5.9942202 | T35: =TTEST('3. Raw Data'!H127:H131,'3. Raw Data'!H2:H6,2,3) -> 0.0040581866 | U35: =IF(T35<0.05,"yes","tie") -> yes | V35: =IF(G35<1,"Excellent",IF(G35<2,"Good",IF(G35<4,"Fair","Poor"))) -> Fair
A36: 27 | B36: RoscaV2-PowerPlan | C36: community | D36: 5 | E36: =AVERAGE('3. Raw Data'!H132:H136) -> 227.40214 | F36: =STDEV('3. Raw Data'!H132:H136) -> 1.1490887 | G36: =F36/E36*100 -> 0.50531131 | H36: =TINV(0.05,5-1)*F36/SQRT(5) -> 1.4267821 | I36: =AVERAGE('3. Raw Data'!I132:I136) -> 230.69366 | J36: =AVERAGE('3. Raw Data'!J132:J136) -> 174.27693 | K36: =AVERAGE('3. Raw Data'!K132:K136) -> 154.26265 | L36: =AVERAGE('3. Raw Data'!L132:L136) -> 154.40052 | M36: =AVERAGE('3. Raw Data'!M132:M136) -> 85.253337 | N36: =AVERAGE('3. Raw Data'!N132:N136) -> 39.868701 | O36: =AVERAGE('3. Raw Data'!O132:O136) -> 368.05093 | P36: =AVERAGE('3. Raw Data'!R132:R136) -> 11.41986 | Q36: =AVERAGE('3. Raw Data'!S132:S136) -> 0.021995833 | R36: =E36-E10 -> -14.617239 | S36: =(E36-E10)/E10*100 -> -6.0396978 | T36: =TTEST('3. Raw Data'!H132:H136,'3. Raw Data'!H2:H6,2,3) -> 4.1174029e-08 | U36: =IF(T36<0.05,"yes","tie") -> yes | V36: =IF(G36<1,"Excellent",IF(G36<2,"Good",IF(G36<4,"Fair","Poor"))) -> Excellent
A37: 28 | B37: GPU-BOOSTER-PowerPlan | C37: community | D37: 5 | E37: =AVERAGE('3. Raw Data'!H137:H141) -> 227.28952 | F37: =STDEV('3. Raw Data'!H137:H141) -> 0.55048221 | G37: =F37/E37*100 -> 0.24219428 | H37: =TINV(0.05,5-1)*F37/SQRT(5) -> 0.68351394 | I37: =AVERAGE('3. Raw Data'!I137:I141) -> 229.56102 | J37: =AVERAGE('3. Raw Data'!J137:J141) -> 177.25876 | K37: =AVERAGE('3. Raw Data'!K137:K141) -> 159.45955 | L37: =AVERAGE('3. Raw Data'!L137:L141) -> 159.59555 | M37: =AVERAGE('3. Raw Data'!M137:M141) -> 89.891791 | N37: =AVERAGE('3. Raw Data'!N137:N141) -> 42.053369 | O37: =AVERAGE('3. Raw Data'!O137:O141) -> 420.57473 | P37: =AVERAGE('3. Raw Data'!R137:R141) -> 11.439111 | Q37: =AVERAGE('3. Raw Data'!S137:S141) -> 0.020536758 | R37: =E37-E10 -> -14.729862 | S37: =(E37-E10)/E10*100 -> -6.0862326 | T37: =TTEST('3. Raw Data'!H137:H141,'3. Raw Data'!H2:H6,2,3) -> 9.0423527e-09 | U37: =IF(T37<0.05,"yes","tie") -> yes | V37: =IF(G37<1,"Excellent",IF(G37<2,"Good",IF(G37<4,"Fair","Poor"))) -> Excellent
A38: 29 | B38: IIIEXOIII-PowerPlan | C38: community | D38: 5 | E38: =AVERAGE('3. Raw Data'!H142:H146) -> 226.96542 | F38: =STDEV('3. Raw Data'!H142:H146) -> 0.7732654 | G38: =F38/E38*100 -> 0.34069745 | H38: =TINV(0.05,5-1)*F38/SQRT(5) -> 0.96013581 | I38: =AVERAGE('3. Raw Data'!I142:I146) -> 229.03286 | J38: =AVERAGE('3. Raw Data'!J142:J146) -> 177.86601 | K38: =AVERAGE('3. Raw Data'!K142:K146) -> 159.18965 | L38: =AVERAGE('3. Raw Data'!L142:L146) -> 160.17146 | M38: =AVERAGE('3. Raw Data'!M142:M146) -> 93.894649 | N38: =AVERAGE('3. Raw Data'!N142:N146) -> 40.842246 | O38: =AVERAGE('3. Raw Data'!O142:O146) -> 395.2109 | P38: =AVERAGE('3. Raw Data'!R142:R146) -> 10.874201 | Q38: =AVERAGE('3. Raw Data'!S142:S146) -> 0.01614652 | R38: =E38-E10 -> -15.053958 | S38: =(E38-E10)/E10*100 -> -6.2201455 | T38: =TTEST('3. Raw Data'!H142:H146,'3. Raw Data'!H2:H6,2,3) -> 2.2739816e-09 | U38: =IF(T38<0.05,"yes","tie") -> yes | V38: =IF(G38<1,"Excellent",IF(G38<2,"Good",IF(G38<4,"Fair","Poor"))) -> Excellent
A39: 30 | B39: Hybred-Low-Latency-PowerPlan | C39: community | D39: 5 | E39: =AVERAGE('3. Raw Data'!H147:H151) -> 226.61668 | F39: =STDEV('3. Raw Data'!H147:H151) -> 1.1318188 | G39: =F39/E39*100 -> 0.49944195 | H39: =TINV(0.05,5-1)*F39/SQRT(5) -> 1.4053386 | I39: =AVERAGE('3. Raw Data'!I147:I151) -> 229.14664 | J39: =AVERAGE('3. Raw Data'!J147:J151) -> 177.43064 | K39: =AVERAGE('3. Raw Data'!K147:K151) -> 157.58473 | L39: =AVERAGE('3. Raw Data'!L147:L151) -> 131.10833 | M39: =AVERAGE('3. Raw Data'!M147:M151) -> 75.492699 | N39: =AVERAGE('3. Raw Data'!N147:N151) -> 33.671458 | O39: =AVERAGE('3. Raw Data'!O147:O151) -> 391.64428 | P39: =AVERAGE('3. Raw Data'!R147:R151) -> 28.294421 | Q39: =AVERAGE('3. Raw Data'!S147:S151) -> 0.019166841 | R39: =E39-E10 -> -15.402697 | S39: =(E39-E10)/E10*100 -> -6.3642411 | T39: =TTEST('3. Raw Data'!H147:H151,'3. Raw Data'!H2:H6,2,3) -> 2.3801484e-08 | U39: =IF(T39<0.05,"yes","tie") -> yes | V39: =IF(G39<1,"Excellent",IF(G39<2,"Good",IF(G39<4,"Fair","Poor"))) -> Excellent
A40: 31 | B40: MSFT-High-Performance-PowerPlan | C40: MSFT stock | D40: 5 | E40: =AVERAGE('3. Raw Data'!H152:H156) -> 226.53446 | F40: =STDEV('3. Raw Data'!H152:H156) -> 0.33354032 | G40: =F40/E40*100 -> 0.14723602 | H40: =TINV(0.05,5-1)*F40/SQRT(5) -> 0.41414501 | I40: =AVERAGE('3. Raw Data'!I152:I156) -> 228.73918 | J40: =AVERAGE('3. Raw Data'!J152:J156) -> 177.14577 | K40: =AVERAGE('3. Raw Data'!K152:K156) -> 157.68577 | L40: =AVERAGE('3. Raw Data'!L152:L156) -> 157.6021 | M40: =AVERAGE('3. Raw Data'!M152:M156) -> 84.425415 | N40: =AVERAGE('3. Raw Data'!N152:N156) -> 40.535875 | O40: =AVERAGE('3. Raw Data'!O152:O156) -> 406.99755 | P40: =AVERAGE('3. Raw Data'!R152:R156) -> 10.983515 | Q40: =AVERAGE('3. Raw Data'!S152:S156) -> 0.022067407 | R40: =E40-E10 -> -15.484916 | S40: =(E40-E10)/E10*100 -> -6.3982133 | T40: =TTEST('3. Raw Data'!H152:H156,'3. Raw Data'!H2:H6,2,3) -> 1.4609683e-07 | U40: =IF(T40<0.05,"yes","tie") -> yes | V40: =IF(G40<1,"Excellent",IF(G40<2,"Good",IF(G40<4,"Fair","Poor"))) -> Excellent
A41: 32 | B41: GTweaks-PowerPlan | C41: community | D41: 5 | E41: =AVERAGE('3. Raw Data'!H157:H161) -> 226.29303 | F41: =STDEV('3. Raw Data'!H157:H161) -> 0.75380831 | G41: =F41/E41*100 -> 0.33311159 | H41: =TINV(0.05,5-1)*F41/SQRT(5) -> 0.93597664 | I41: =AVERAGE('3. Raw Data'!I157:I161) -> 228.18587 | J41: =AVERAGE('3. Raw Data'!J157:J161) -> 176.67524 | K41: =AVERAGE('3. Raw Data'!K157:K161) -> 157.2712 | L41: =AVERAGE('3. Raw Data'!L157:L161) -> 156.59759 | M41: =AVERAGE('3. Raw Data'!M157:M161) -> 83.321644 | N41: =AVERAGE('3. Raw Data'!N157:N161) -> 40.089737 | O41: =AVERAGE('3. Raw Data'!O157:O161) -> 405.79406 | P41: =AVERAGE('3. Raw Data'!R157:R161) -> 11.119841 | Q41: =AVERAGE('3. Raw Data'!S157:S161) -> 0.025054963 | R41: =E41-E10 -> -15.726349 | S41: =(E41-E10)/E10*100 -> -6.497971 | T41: =TTEST('3. Raw Data'!H157:H161,'3. Raw Data'!H2:H6,2,3) -> 1.6006033e-09 | U41: =IF(T41<0.05,"yes","tie") -> yes | V41: =IF(G41<1,"Excellent",IF(G41<2,"Good",IF(G41<4,"Fair","Poor"))) -> Excellent
A42: 33 | B42: Kizzimo-PowerPlan | C42: community | D42: 5 | E42: =AVERAGE('3. Raw Data'!H162:H166) -> 223.53808 | F42: =STDEV('3. Raw Data'!H162:H166) -> 0.43898487 | G42: =F42/E42*100 -> 0.19638036 | H42: =TINV(0.05,5-1)*F42/SQRT(5) -> 0.54507171 | I42: =AVERAGE('3. Raw Data'!I162:I166) -> 225.62905 | J42: =AVERAGE('3. Raw Data'!J162:J166) -> 173.83433 | K42: =AVERAGE('3. Raw Data'!K162:K166) -> 152.93146 | L42: =AVERAGE('3. Raw Data'!L162:L166) -> 153.94013 | M42: =AVERAGE('3. Raw Data'!M162:M166) -> 88.064192 | N42: =AVERAGE('3. Raw Data'!N162:N166) -> 40.778082 | O42: =AVERAGE('3. Raw Data'!O162:O166) -> 380.75021 | P42: =AVERAGE('3. Raw Data'!R162:R166) -> 11.247336 | Q42: =AVERAGE('3. Raw Data'!S162:S166) -> 0.025372128 | R42: =E42-E10 -> -18.481301 | S42: =(E42-E10)/E10*100 -> -7.6362895 | T42: =TTEST('3. Raw Data'!H162:H166,'3. Raw Data'!H2:H6,2,3) -> 1.0406877e-08 | U42: =IF(T42<0.05,"yes","tie") -> yes | V42: =IF(G42<1,"Excellent",IF(G42<2,"Good",IF(G42<4,"Fair","Poor"))) -> Excellent
A43: 34 | B43: XNRL-PowerPlan | C43: community | D43: 5 | E43: =AVERAGE('3. Raw Data'!H167:H171) -> 222.62069 | F43: =STDEV('3. Raw Data'!H167:H171) -> 0.87683432 | G43: =F43/E43*100 -> 0.3938692 | H43: =TINV(0.05,5-1)*F43/SQRT(5) -> 1.0887336 | I43: =AVERAGE('3. Raw Data'!I167:I171) -> 225.78429 | J43: =AVERAGE('3. Raw Data'!J167:J171) -> 173.0365 | K43: =AVERAGE('3. Raw Data'!K167:K171) -> 153.81828 | L43: =AVERAGE('3. Raw Data'!L167:L171) -> 153.90437 | M43: =AVERAGE('3. Raw Data'!M167:M171) -> 84.457083 | N43: =AVERAGE('3. Raw Data'!N167:N171) -> 37.761371 | O43: =AVERAGE('3. Raw Data'!O167:O171) -> 472.76626 | P43: =AVERAGE('3. Raw Data'!R167:R171) -> 11.043096 | Q43: =AVERAGE('3. Raw Data'!S167:S171) -> 0.019483851 | R43: =E43-E10 -> -19.39869 | S43: =(E43-E10)/E10*100 -> -8.0153458 | T43: =TTEST('3. Raw Data'!H167:H171,'3. Raw Data'!H2:H6,2,3) -> 4.3827815e-10 | U43: =IF(T43<0.05,"yes","tie") -> yes | V43: =IF(G43<1,"Excellent",IF(G43<2,"Good",IF(G43<4,"Fair","Poor"))) -> Excellent
A44: 35 | B44: MSFT-UltimatePerformance-PowerPlan | C44: MSFT stock | D44: 5 | E44: =AVERAGE('3. Raw Data'!H172:H176) -> 222.19587 | F44: =STDEV('3. Raw Data'!H172:H176) -> 2.4608799 | G44: =F44/E44*100 -> 1.1075273 | H44: =TINV(0.05,5-1)*F44/SQRT(5) -> 3.055586 | I44: =AVERAGE('3. Raw Data'!I172:I176) -> 225.39424 | J44: =AVERAGE('3. Raw Data'!J172:J176) -> 172.03789 | K44: =AVERAGE('3. Raw Data'!K172:K176) -> 150.40901 | L44: =AVERAGE('3. Raw Data'!L172:L176) -> 152.33629 | M44: =AVERAGE('3. Raw Data'!M172:M176) -> 89.553095 | N44: =AVERAGE('3. Raw Data'!N172:N176) -> 39.599478 | O44: =AVERAGE('3. Raw Data'!O172:O176) -> 407.18694 | P44: =AVERAGE('3. Raw Data'!R172:R176) -> 11.042807 | Q44: =AVERAGE('3. Raw Data'!S172:S176) -> 0.019528602 | R44: =E44-E10 -> -19.823508 | S44: =(E44-E10)/E10*100 -> -8.1908762 | T44: =TTEST('3. Raw Data'!H172:H176,'3. Raw Data'!H2:H6,2,3) -> 1.4112436e-05 | U44: =IF(T44<0.05,"yes","tie") -> yes | V44: =IF(G44<1,"Excellent",IF(G44<2,"Good",IF(G44<4,"Fair","Poor"))) -> Good
...

Sheet 5. Graphs
B2: Graphs
B3: All charts are built live from Sheet 4 (Statistical Analysis). Plans are ranked best-to-worst by mean Avg FPS. The plan NAME is printed on the axis next to each bar; the number is shown at the end of each bar.
B5: Chart 1 - Mean Avg FPS by power plan (ranked)
B6: Average frames per second per plan (mean of 5 runs). Longer bar = faster - this is the headline ranking. Each bar is labelled with its plan name on the left and its exact FPS at the bar end. Microsoft stock plans are included as neutral references.
