Workbook

Sheet 1. Test Setup
B2: Windows Power-Plan DPC/ISR Latency Benchmark - Test Setup & Methodology
B3: Validation of kernel interrupt/DPC latency per power plan - integrity-first, repeated captures (lower microseconds = better)
B5: 1 - System Under Test (Hardware) | E5: HOW TO READ THIS WORKBOOK
B6: CPU | C6: Intel(R) Core(TM) i5-10400F CPU @ 2.90GHz (6 cores / 12 threads) | E6: Sheet 2 - Glossary
B7: GPU | C7: AMD Radeon RX 5700 XT (same rig as the FPS benchmark) | E7: Plain-language explanation of DPC, ISR, percentiles, %CPU-busy and every term used here. Start here.
B8: Machine | C8: WORKSTATION
E9: Sheet 3 - Raw Data
B10: 2 - Operating System & Power Plans | E10: Every run (117 rows): DPC/ISR percentiles, interrupt load, CPU clock, plus a per-second DPC-load series.
B11: Operating System | C11: Windows 11 Pro (Build 26200)
B12: What changed | C12: Windows Power Plan only - 39 plans tested back-to-back on the identical OS image and hardware. Nothing else altered between conditions. | E12: Sheet 4 - Statistical Analysis
B13: Stock references | C13: 'High performance' and 'Ultimate Performance' are Microsoft's built-in plans, kept as neutral baselines. | E13: Per-plan mean +/- SD, CV%, 95% CI, Welch t-test vs the best plan. Live formulas from Sheet 3.
B15: 3 - Workload / Scene | E15: Sheet 5 - Graphs
B16: Scene | C16: Same custom 1v1 map, fixed STATIC scene as the FPS test. Identical scene captured repeatedly so the only variable is the power plan. | E16: All charts, each with a caption. Lower bars = better (less latency / load).
B18: 4 - Capture Tool & Protocol | E18: Sheet 6 - Verdicts
B19: Capture tool | C19: Custom in-house tool (Measure-Latency.ps1 v1.1.0), built by me. | E19: Strict analyst verdict per plan + headline recommendation.
B20: Measurement engine | C20: Windows Performance Toolkit xperf - kernel ETW trace of DPC (Deferred Procedure Call) and ISR (Interrupt Service Routine) latency.
B21: Captures per plan | C21: 3 repeated runs per plan | E21: Lower is better
B22: Capture length | C22: 30 s requested per run (~40 s trace incl. overhead) | E22: Unlike the FPS workbook, every metric here is a latency or load figure: SMALLER numbers are better.
B23: Warm-up | C23: First 5 s discarded; CPU-load metrics computed on the post-warm-up window. Percentiles are whole-trace (histogram-based, cannot be re-trimmed).
B24: Primary metric | C24: DPC 99th-percentile latency (us) - the worst-case DPC duration that drives micro-stutter & input-lag spikes. Lower is better.
B25: Supporting metrics | C25: DPC p999, DPC/ISR %CPU-busy & us/s (interrupt load), ISR p99, combined kernel load, CPU clock held.
B27: 5 - Dataset Integrity Summary
B28: Total valid runs | C28: 117 (39 plans x 3 runs)
B29: Lost ETW events / buffers | C29: 0 across every run - clean traces.
B30: CPU clock during tests | C30: Held at ~99-100% of base on ALL plans (eff. ~2889 MHz). No plan throttled, so differences are pure DPC/ISR behaviour, not clock speed.
B31: DPC source | C31: DPC time dominated by the GPU driver (dxgkrnl.sys) on 100%% of runs - expected for a GPU workload.
B32: Absolute-latency context | C32: All plans land at DPC p99 = 115-196 us, well below the ~500-1000 us range where DPC latency becomes audibly/perceptibly problematic. Differences are real and measurable, but every plan is in healthy territory.
B33: Run-to-run repeatability | C33: Median per-plan CV = 0.92% on DPC p99 (5 plans are noisier - flagged in Verdicts).

Sheet 2. Glossary
B2: Glossary - latency terms in plain language
B3: This is a DPC/ISR latency benchmark: every number is microseconds (us) of latency or % of CPU spent on interrupts. SMALLER = better.
B5: A. Latency & load metrics (lower is better)
B6: Term | C6: Plain-language meaning | D6: Better when | E6: Found in
B7: DPC | C7: Deferred Procedure Call - lower-priority kernel work a driver queues to run just after an interrupt. Long DPCs block other work and cause micro-stutter, audio pops and input-lag spikes. | D7: Lower | E7: whole workbook
B8: ISR | C8: Interrupt Service Routine - the immediate handler that runs the instant a device interrupts the CPU. Should be very short. | D8: Lower | E8: Raw P-R
B9: p50 / p90 (us) | C9: Median and 90th-percentile latency, in microseconds. Typical-case behaviour. | D9: Lower | E9: Raw F,G,N,O
B10: DPC p99 (us) | C10: 99th-percentile DPC latency = worst-case among all but the rarest 1% of DPCs. THE headline responsiveness metric in this workbook. | D10: Lower | E10: Raw H / Stats E
B11: DPC p999 (us) | C11: 99.9th percentile - the deepest spikes. Here it is limited by the tool's histogram bands, so it barely separates plans. | D11: Lower | E11: Raw I / Stats I
B12: DPC / ISR %CPU busy | C12: Share of total CPU time spent inside DPCs / ISRs (averaged over all 12 logical CPUs). Interrupt overhead. Warm-up-trimmed. | D12: Lower | E12: Raw J,R / Stats J,N
B13: DPC / ISR us/s | C13: Microseconds of DPC/ISR time per second of wall-clock - another view of interrupt load. | D13: Lower | E13: Raw K,T
B14: Combined %CPU busy | C14: DPC + ISR load added together - one number for total kernel interrupt overhead. | D14: Lower | E14: Raw S / Stats O
B15: DPC max band (us) | C15: Upper edge of the slowest latency bucket that had any DPCs - the single worst spike region. | D15: Lower | E15: Raw L
B16: DPC >64us tail % | C16: Percentage of DPCs that took longer than 64 us - how often long DPCs happen. | D16: Lower | E16: Raw M
B18: B. Capture & integrity terms
B19: Term | C19: Plain-language meaning | D19: Better when | E19: Found in
B20: Run | C20: One ~40 s xperf capture. Each plan was tested 3 times (Run 1-3). | D20: Neutral | E20: Raw B
B21: Trace (s) | C21: Length of the captured trace (~40 s incl. overhead beyond the 30 s requested). | D21: Neutral | E21: Raw D
B22: Lost evt+buf | C22: ETW events/buffers dropped during capture. 0 = a clean, trustworthy trace. | D22: 0 | E22: Raw E
B23: Warm-up | C23: First 5 s discarded for the load metrics. Percentiles are whole-trace (histogram-based, cannot be re-trimmed). | D23: Neutral | E23: method
B24: CPU perf % / eff MHz | C24: How hard the CPU ran. ~99% / ~2890 MHz on every plan = no throttling, so results reflect DPC/ISR scheduling only. | D24: context | E24: Raw U,V
B25: Per-second DPC %busy | C25: DPC load measured each second of the run - shows stability over time within one capture (Chart 4). | D25: Lower/flatter | E25: Raw s01...
B27: C. Statistical terms
B28: Term | C28: Plain-language meaning | D28: Better when | E28: Found in
B29: Mean | C29: Average of the 3 runs. | D29: Neutral | E29: Stats E...
B30: +/- SD | C30: Spread of the 3 runs around the mean. Small = runs agreed. | D30: Lower | E30: Stats F
B31: CV % | C31: SD / mean as a %. Fair consistency comparison across plans. | D31: Lower | E31: Stats G
B32: 95% CI +/- | C32: The mean is reliable to about +/- this (n=3, df=2, t=4.303). Wide because only 3 runs. | D32: Smaller | E32: Stats H
B33: Delta vs best (us / %) | C33: How much higher this plan's DPC p99 is than the #1 plan. | D33: Closer to 0 | E33: Stats Q,R
B34: Welch p vs best | C34: Probability the gap to #1 is just luck. p<0.05 = real; 'tie' = not separable from the best. | D34: Neutral | E34: Stats S
B35: Sig? / Stat. tie | C35: 'yes' = significantly worse than #1. 'tie' = as good as #1. | D35: 'tie' good | E35: Stats T
B36: Repeatability | C36: From DPC p99 CV%: Excellent <1, Good <2, Fair <4, Poor >=4. | D36: Excellent | E36: Stats U
B37: ANOVA (F,p) | C37: One test: do the plans really differ beyond run noise? Tiny p (~4e-30) = yes. | D37: Neutral | E37: Stats top
B38: MSFT stock | C38: Microsoft built-in plans (High performance, Ultimate Performance) - neutral baselines. | D38: Neutral | E38: highlighted

Sheet 3. Raw Data
A1: Plan | B1: Run | C1: Windows Plan | D1: Trace (s) | E1: Lost evt+buf | F1: DPC p50 (us) | G1: DPC p90 (us) | H1: DPC p99 (us) | I1: DPC p999 (us) | J1: DPC %CPU busy | K1: DPC us/s | L1: DPC max band (us) | M1: DPC >64us tail % | N1: ISR p50 (us) | O1: ISR p90 (us) | P1: ISR p99 (us) | Q1: ISR p999 (us) | R1: ISR %CPU busy | S1: Comb %CPU busy | T1: Comb us/s | U1: CPU perf % avg | V1: CPU eff MHz | W1: Per-second DPC %CPU-busy -> | X1: s01 | Y1: s02 | Z1: s03 | AA1: s04 | AB1: s05 | AC1: s06 | AD1: s07 | AE1: s08 | AF1: s09 | AG1: s10 | AH1: s11 | AI1: s12 | AJ1: s13 | AK1: s14 | AL1: s15 | AM1: s16 | AN1: s17 | AO1: s18 | AP1: s19 | AQ1: s20 | AR1: s21 | AS1: s22 | AT1: s23 | AU1: s24 | AV1: s25 | AW1: s26 | AX1: s27 | AY1: s28 | AZ1: s29 | BA1: s30 | BB1: s31 | BC1: s32 | BD1: s33 | BE1: s34 | BF1: s35 | BG1: s36 | BH1: s37 | BI1: s38 | BJ1: s39 | BK1: s40 | BL1: s41 | BM1: s42 | BN1: s43 | BO1: s44 | BP1: s45
A2: Kizzimo's Extreme Low Latency | B2: 1 | C2: Kizzimo's Extreme Low Latency | D2: 39.83 | E2: 0 | F2: 6.88 | G2: 25.5 | H2: 115.35 | I2: 240.37 | J2: 1.4580378 | K2: 179243.85 | L2: 512 | M2: 1.7446 | N2: 9.46 | O2: 15.98 | P2: 51.73 | Q2: 62.85 | R2: 0.42423514 | S2: 1.882273 | T2: 231396.55 | U2: 99.3 | V2: 2884 | X2: 1.488 | Y2: 1.501 | Z2: 1.502 | AA2: 1.486 | AB2: 1.48 | AC2: 1.495 | AD2: 1.515 | AE2: 1.488 | AF2: 1.48 | AG2: 1.503 | AH2: 1.483 | AI2: 1.495 | AJ2: 1.483 | AK2: 1.502 | AL2: 1.482 | AM2: 1.484 | AN2: 1.488 | AO2: 1.502 | AP2: 1.495 | AQ2: 1.501 | AR2: 1.5 | AS2: 1.51 | AT2: 1.515 | AU2: 1.477 | AV2: 1.474 | AW2: 1.502 | AX2: 1.504 | AY2: 1.503 | AZ2: 1.466 | BA2: 1.496 | BB2: 1.505 | BC2: 1.495 | BD2: 1.5 | BE2: 1.511 | BF2: 1.493 | BG2: 1.523 | BH2: 1.486 | BI2: 1.502 | BJ2: 1.51 | BK2: 1.516 | BL2: 1.504 | BM2: 0.061
A3: Kizzimo's Extreme Low Latency | B3: 2 | C3: Kizzimo's Extreme Low Latency | D3: 39.8 | E3: 0 | F3: 6.89 | G3: 25.45 | H3: 115.23 | I3: 240.27 | J3: 1.4551919 | K3: 179049.96 | L3: 2097152 | M3: 1.7518 | N3: 9.43 | O3: 15.98 | P3: 52.17 | Q3: 62.97 | R3: 0.42228919 | S3: 1.8774811 | T3: 231005.05 | U3: 99.4 | V3: 2887 | X3: 1.635 | Y3: 1.532 | Z3: 1.496 | AA3: 1.505 | AB3: 1.494 | AC3: 1.46 | AD3: 1.504 | AE3: 1.493 | AF3: 1.501 | AG3: 1.498 | AH3: 1.5 | AI3: 1.487 | AJ3: 1.479 | AK3: 1.521 | AL3: 1.503 | AM3: 1.48 | AN3: 1.487 | AO3: 1.497 | AP3: 1.498 | AQ3: 1.503 | AR3: 1.485 | AS3: 1.497 | AT3: 1.484 | AU3: 1.502 | AV3: 1.479 | AW3: 1.467 | AX3: 1.503 | AY3: 1.495 | AZ3: 1.497 | BA3: 1.493 | BB3: 1.486 | BC3: 1.489 | BD3: 1.491 | BE3: 1.488 | BF3: 1.503 | BG3: 1.498 | BH3: 1.499 | BI3: 1.498 | BJ3: 1.495 | BK3: 1.503 | BL3: 1.525 | BM3: 0.057
A4: Kizzimo's Extreme Low Latency | B4: 3 | C4: Kizzimo's Extreme Low Latency | D4: 39.79 | E4: 0 | F4: 6.9 | G4: 25.46 | H4: 115.16 | I4: 240.24 | J4: 1.4545 | K4: 179293.87 | L4: 512 | M4: 1.7534 | N4: 9.42 | O4: 15.97 | P4: 51.95 | Q4: 62.89 | R4: 0.42174595 | S4: 1.8762459 | T4: 231281.63 | U4: 99.5 | V4: 2889 | X4: 1.452 | Y4: 1.499 | Z4: 1.515 | AA4: 1.495 | AB4: 1.496 | AC4: 1.507 | AD4: 1.494 | AE4: 1.499 | AF4: 1.486 | AG4: 1.483 | AH4: 1.521 | AI4: 1.488 | AJ4: 1.468 | AK4: 1.493 | AL4: 1.495 | AM4: 1.498 | AN4: 1.471 | AO4: 1.513 | AP4: 1.493 | AQ4: 1.512 | AR4: 1.481 | AS4: 1.51 | AT4: 1.502 | AU4: 1.51 | AV4: 1.484 | AW4: 1.492 | AX4: 1.478 | AY4: 1.492 | AZ4: 1.489 | BA4: 1.487 | BB4: 1.498 | BC4: 1.484 | BD4: 1.519 | BE4: 1.496 | BF4: 1.501 | BG4: 1.488 | BH4: 1.49 | BI4: 1.504 | BJ4: 1.499 | BK4: 1.511 | BL4: 1.479 | BM4: 0
A5: Lowest Latency | B5: 1 | C5: Lowest Latency | D5: 47.09 | E5: 0 | F5: 6.66 | G5: 29.36 | H5: 169.77 | I5: 247.43 | J5: 0.89723636 | K5: 107868.29 | L5: 512 | M5: 3.3125 | N5: 9.12 | O5: 17.1 | P5: 56.6 | Q5: 70.27 | R5: 0.41302273 | S5: 1.3102591 | T5: 157489.13 | U5: 99.5 | V5: 2889 | X5: 0.876 | Y5: 0.861 | Z5: 0.888 | AA5: 0.87 | AB5: 0.867 | AC5: 0.873 | AD5: 0.874 | AE5: 0.85 | AF5: 0.898 | AG5: 0.905 | AH5: 0.878 | AI5: 0.914 | AJ5: 0.911 | AK5: 0.915 | AL5: 0.895 | AM5: 0.902 | AN5: 0.931 | AO5: 0.917 | AP5: 0.895 | AQ5: 0.859 | AR5: 0.927 | AS5: 0.907 | AT5: 0.89 | AU5: 0.892 | AV5: 0.917 | AW5: 0.923 | AX5: 0.903 | AY5: 0.874 | AZ5: 0.887 | BA5: 0.891 | BB5: 0.899 | BC5: 0.901 | BD5: 0.92 | BE5: 0.903 | BF5: 0.894 | BG5: 0.875 | BH5: 0.927 | BI5: 0.897 | BJ5: 0.915 | BK5: 0.875 | BL5: 0.951 | BM5: 0.92 | BN5: 0.904 | BO5: 0.883 | BP5: 0.913
A6: Lowest Latency | B6: 2 | C6: Lowest Latency | D6: 39.86 | E6: 0 | F6: 6.9 | G6: 29.12 | H6: 164.7 | I6: 247.1 | J6: 0.90761081 | K6: 109312.93 | L6: 512 | M6: 3.1891 | N6: 8.53 | O6: 16.13 | P6: 56.15 | Q6: 75.3 | R6: 0.43472703 | S6: 1.3423378 | T6: 161639.36 | U6: 99.5 | V6: 2889 | X6: 0.875 | Y6: 0.926 | Z6: 0.905 | AA6: 0.905 | AB6: 0.884 | AC6: 0.917 | AD6: 0.93 | AE6: 0.914 | AF6: 0.876 | AG6: 0.939 | AH6: 0.911 | AI6: 0.89 | AJ6: 0.846 | AK6: 1.177 | AL6: 1.305 | AM6: 0.935 | AN6: 0.874 | AO6: 0.921 | AP6: 0.912 | AQ6: 0.909 | AR6: 0.878 | AS6: 0.919 | AT6: 0.88 | AU6: 0.913 | AV6: 0.901 | AW6: 0.911 | AX6: 0.906 | AY6: 0.894 | AZ6: 0.885 | BA6: 0.866 | BB6: 0.905 | BC6: 0.888 | BD6: 0.823 | BE6: 0.862 | BF6: 0.871 | BG6: 0.894 | BH6: 0.897 | BI6: 0.867 | BJ6: 0.903 | BK6: 0.883 | BL6: 0.836 | BM6: 0.744
A7: Lowest Latency | B7: 3 | C7: Lowest Latency | D7: 39.93 | E7: 0 | F7: 6.68 | G7: 29.15 | H7: 148.63 | I7: 245.32 | J7: 0.88066216 | K7: 105911.46 | L7: 512 | M7: 3.003 | N7: 9.36 | O7: 18.97 | P7: 57.66 | Q7: 86.63 | R7: 0.4270973 | S7: 1.3077595 | T7: 157242.62 | U7: 99.5 | V7: 2889 | X7: 0.834 | Y7: 0.912 | Z7: 0.878 | AA7: 0.877 | AB7: 0.85 | AC7: 0.883 | AD7: 1.012 | AE7: 0.904 | AF7: 0.842 | AG7: 0.838 | AH7: 0.956 | AI7: 0.921 | AJ7: 0.843 | AK7: 0.852 | AL7: 0.847 | AM7: 0.881 | AN7: 0.866 | AO7: 0.879 | AP7: 0.852 | AQ7: 0.899 | AR7: 0.865 | AS7: 0.893 | AT7: 0.915 | AU7: 0.87 | AV7: 0.828 | AW7: 0.898 | AX7: 0.924 | AY7: 0.88 | AZ7: 0.862 | BA7: 0.893 | BB7: 0.896 | BC7: 0.885 | BD7: 0.867 | BE7: 0.899 | BF7: 0.89 | BG7: 0.889 | BH7: 0.874 | BI7: 0.889 | BJ7: 0.896 | BK7: 0.89 | BL7: 0.829 | BM7: 0.778
A8: _Reticle_ | B8: 1 | C8: <Reticle> | D8: 47.45 | E8: 0 | F8: 5.18 | G8: 28.75 | H8: 154.88 | I8: 245.91 | J8: 0.86820682 | K8: 104310.49 | L8: 512 | M8: 2.9997 | N8: 7.5 | O8: 15.84 | P8: 60.19 | Q8: 119 | R8: 0.45513636 | S8: 1.3233432 | T8: 159012.94 | U8: 99.5 | V8: 2890 | X8: 0.837 | Y8: 0.823 | Z8: 0.811 | AA8: 0.819 | AB8: 0.837 | AC8: 0.815 | AD8: 0.83 | AE8: 0.822 | AF8: 0.842 | AG8: 0.823 | AH8: 0.831 | AI8: 0.838 | AJ8: 0.838 | AK8: 0.834 | AL8: 0.83 | AM8: 0.828 | AN8: 0.855 | AO8: 0.822 | AP8: 0.837 | AQ8: 0.801 | AR8: 0.841 | AS8: 0.814 | AT8: 1.074 | AU8: 1.114 | AV8: 1.433 | AW8: 0.969 | AX8: 0.938 | AY8: 0.926 | AZ8: 0.907 | BA8: 0.903 | BB8: 0.929 | BC8: 0.844 | BD8: 0.857 | BE8: 0.828 | BF8: 0.827 | BG8: 0.839 | BH8: 0.831 | BI8: 0.838 | BJ8: 0.807 | BK8: 0.827 | BL8: 0.84 | BM8: 0.83 | BN8: 0.818 | BO8: 0.826 | BP8: 0.838
A9: _Reticle_ | B9: 2 | C9: <Reticle> | D9: 39.79 | E9: 0 | F9: 5.32 | G9: 28.48 | H9: 173.99 | I9: 247.86 | J9: 0.84118056 | K9: 100954.4 | L9: 512 | M9: 3.1836 | N9: 7.49 | O9: 15.78 | P9: 53.3 | Q9: 63.45 | R9: 0.40217778 | S9: 1.2433583 | T9: 149221.59 | U9: 99.5 | V9: 2889 | X9: 0.808 | Y9: 0.839 | Z9: 0.841 | AA9: 0.824 | AB9: 0.82 | AC9: 0.832 | AD9: 0.841 | AE9: 0.829 | AF9: 0.829 | AG9: 0.833 | AH9: 0.835 | AI9: 0.828 | AJ9: 0.815 | AK9: 0.829 | AL9: 0.83 | AM9: 0.855 | AN9: 0.936 | AO9: 0.892 | AP9: 0.877 | AQ9: 0.89 | AR9: 0.897 | AS9: 0.842 | AT9: 0.767 | AU9: 0.848 | AV9: 0.84 | AW9: 0.831 | AX9: 0.849 | AY9: 0.817 | AZ9: 0.843 | BA9: 0.816 | BB9: 0.851 | BC9: 0.825 | BD9: 0.825 | BE9: 0.833 | BF9: 0.848 | BG9: 0.858 | BH9: 0.838 | BI9: 0.836 | BJ9: 0.847 | BK9: 0.83 | BL9: 0.793
A10: _Reticle_ | B10: 3 | C10: <Reticle> | D10: 39.76 | E10: 0 | F10: 5.17 | G10: 28.42 | H10: 172.29 | I10: 247.63 | J10: 0.84361667 | K10: 101264.65 | L10: 256 | M10: 3.1666 | N10: 7.58 | O10: 15.76 | P10: 52.3 | Q10: 63.2 | R10: 0.39993889 | S10: 1.2435556 | T10: 149262.78 | U10: 99.5 | V10: 2889 | X10: 0.823 | Y10: 0.844 | Z10: 0.835 | AA10: 0.846 | AB10: 0.833 | AC10: 0.848 | AD10: 0.836 | AE10: 0.843 | AF10: 0.833 | AG10: 0.853 | AH10: 0.855 | AI10: 0.847 | AJ10: 0.824 | AK10: 0.861 | AL10: 0.844 | AM10: 0.844 | AN10: 0.838 | AO10: 0.823 | AP10: 0.825 | AQ10: 0.83 | AR10: 0.824 | AS10: 0.843 | AT10: 0.832 | AU10: 0.835 | AV10: 0.837 | AW10: 0.839 | AX10: 0.848 | AY10: 0.838 | AZ10: 0.834 | BA10: 0.864 | BB10: 0.856 | BC10: 0.86 | BD10: 0.835 | BE10: 0.834 | BF10: 0.855 | BG10: 0.947 | BH10: 0.856 | BI10: 0.838 | BJ10: 0.853 | BK10: 0.855 | BL10: 0.783
A11: amit's low latency powerplan | B11: 1 | C11: amit's low latency powerplan | D11: 39.79 | E11: 0 | F11: 5 | G11: 28.17 | H11: 172.18 | I11: 247.66 | J11: 0.83775556 | K11: 100556.8 | L11: 512 | M11: 3.0968 | N11: 7.38 | O11: 15.63 | P11: 51.55 | Q11: 63.38 | R11: 0.39806111 | S11: 1.2358167 | T11: 148335.47 | U11: 99.4 | V11: 2886 | X11: 0.838 | Y11: 0.879 | Z11: 0.886 | AA11: 0.884 | AB11: 0.876 | AC11: 0.895 | AD11: 0.893 | AE11: 0.88 | AF11: 0.874 | AG11: 0.838 | AH11: 0.832 | AI11: 0.823 | AJ11: 0.83 | AK11: 0.832 | AL11: 0.829 | AM11: 0.822 | AN11: 0.827 | AO11: 0.828 | AP11: 0.83 | AQ11: 0.834 | AR11: 0.836 | AS11: 0.829 | AT11: 0.84 | AU11: 0.842 | AV11: 0.889 | AW11: 0.86 | AX11: 0.857 | AY11: 0.847 | AZ11: 0.841 | BA11: 0.836 | BB11: 0.844 | BC11: 0.828 | BD11: 0.835 | BE11: 0.842 | BF11: 0.836 | BG11: 0.825 | BH11: 0.834 | BI11: 0.821 | BJ11: 0.84 | BK11: 0.831 | BL11: 0.683
A12: amit's low latency powerplan | B12: 2 | C12: amit's low latency powerplan | D12: 39.77 | E12: 0 | F12: 4.92 | G12: 28.27 | H12: 172.86 | I12: 247.71 | J12: 0.83112778 | K12: 99771.317 | L12: 512 | M12: 3.1612 | N12: 7.17 | O12: 15.63 | P12: 51.96 | Q12: 63.58 | R12: 0.39254722 | S12: 1.223675 | T12: 146883.76 | U12: 99.5 | V12: 2889 | X12: 0.809 | Y12: 0.841 | Z12: 0.844 | AA12: 0.833 | AB12: 0.818 | AC12: 0.847 | AD12: 0.823 | AE12: 0.836 | AF12: 0.821 | AG12: 0.832 | AH12: 0.836 | AI12: 0.827 | AJ12: 0.797 | AK12: 0.829 | AL12: 0.823 | AM12: 0.836 | AN12: 0.831 | AO12: 0.83 | AP12: 0.845 | AQ12: 0.838 | AR12: 0.841 | AS12: 0.835 | AT12: 0.838 | AU12: 0.848 | AV12: 0.821 | AW12: 0.821 | AX12: 0.828 | AY12: 0.837 | AZ12: 0.838 | BA12: 0.832 | BB12: 0.843 | BC12: 0.841 | BD12: 0.83 | BE12: 0.827 | BF12: 0.842 | BG12: 0.843 | BH12: 0.832 | BI12: 0.831 | BJ12: 0.823 | BK12: 0.837 | BL12: 0.784
A13: amit's low latency powerplan | B13: 3 | C13: amit's low latency powerplan | D13: 39.75 | E13: 0 | F13: 5.06 | G13: 28.16 | H13: 170.21 | I13: 247.44 | J13: 0.84803611 | K13: 101827.96 | L13: 512 | M13: 3.0651 | N13: 7.39 | O13: 15.63 | P13: 51.65 | Q13: 63.48 | R13: 0.40440278 | S13: 1.2524389 | T13: 150382.85 | U13: 99.6 | V13: 2892 | X13: 0.822 | Y13: 0.833 | Z13: 0.83 | AA13: 0.526 | AB13: 0.802 | AC13: 0.89 | AD13: 0.89 | AE13: 0.878 | AF13: 0.869 | AG13: 0.871 | AH13: 0.873 | AI13: 0.878 | AJ13: 0.888 | AK13: 0.874 | AL13: 0.861 | AM13: 0.829 | AN13: 0.822 | AO13: 0.818 | AP13: 0.847 | AQ13: 0.845 | AR13: 0.843 | AS13: 0.832 | AT13: 0.843 | AU13: 0.838 | AV13: 0.831 | AW13: 0.837 | AX13: 0.832 | AY13: 0.818 | AZ13: 0.843 | BA13: 0.826 | BB13: 0.924 | BC13: 0.873 | BD13: 0.827 | BE13: 0.835 | BF13: 0.851 | BG13: 0.84 | BH13: 0.834 | BI13: 0.819 | BJ13: 0.836 | BK13: 0.844 | BL13: 0.771
A14: Mitstas IDLE ENABLED | B14: 1 | C14: Mitstas IDLE ENABLED | D14: 39.76 | E14: 0 | F14: 2.81 | G14: 30.79 | H14: 160.53 | I14: 246.48 | J14: 0.87359722 | K14: 104896.19 | L14: 512 | M14: 3.5648 | N14: 9.51 | O14: 17.9 | P14: 61.82 | Q14: 120.37 | R14: 0.51137222 | S14: 1.3849694 | T14: 166334.17 | U14: 99.7 | V14: 2895 | X14: 0.842 | Y14: 0.855 | Z14: 0.855 | AA14: 0.85 | AB14: 0.844 | AC14: 0.828 | AD14: 0.856 | AE14: 0.839 | AF14: 0.837 | AG14: 0.831 | AH14: 0.822 | AI14: 0.849 | AJ14: 0.82 | AK14: 0.812 | AL14: 0.848 | AM14: 0.816 | AN14: 0.822 | AO14: 0.855 | AP14: 1.137 | AQ14: 1.046 | AR14: 0.96 | AS14: 0.958 | AT14: 0.975 | AU14: 0.91 | AV14: 0.928 | AW14: 0.93 | AX14: 0.948 | AY14: 0.862 | AZ14: 0.852 | BA14: 0.837 | BB14: 0.865 | BC14: 0.842 | BD14: 0.84 | BE14: 0.828 | BF14: 0.848 | BG14: 0.858 | BH14: 0.835 | BI14: 0.841 | BJ14: 0.87 | BK14: 0.854 | BL14: 0.791
A15: Mitstas IDLE ENABLED | B15: 2 | C15: Mitstas IDLE ENABLED | D15: 39.75 | E15: 0 | F15: 2.89 | G15: 29.85 | H15: 179.25 | I15: 248.33 | J15: 0.83776667 | K15: 100560.51 | L15: 256 | M15: 3.5326 | N15: 9.4 | O15: 15.92 | P15: 51.67 | Q15: 62.94 | R15: 0.44813333 | S15: 1.2859 | T15: 154348.46 | U15: 99.6 | V15: 2893 | X15: 0.828 | Y15: 0.847 | Z15: 0.855 | AA15: 0.843 | AB15: 0.848 | AC15: 0.845 | AD15: 0.838 | AE15: 0.856 | AF15: 0.835 | AG15: 0.831 | AH15: 0.85 | AI15: 0.827 | AJ15: 0.838 | AK15: 0.861 | AL15: 0.845 | AM15: 0.867 | AN15: 0.484 | AO15: 0.602 | AP15: 0.892 | AQ15: 0.879 | AR15: 0.871 | AS15: 0.868 | AT15: 0.875 | AU15: 0.873 | AV15: 0.88 | AW15: 0.869 | AX15: 0.885 | AY15: 0.885 | AZ15: 0.851 | BA15: 0.855 | BB15: 0.843 | BC15: 0.861 | BD15: 0.848 | BE15: 0.856 | BF15: 0.859 | BG15: 0.845 | BH15: 0.832 | BI15: 0.845 | BJ15: 0.846 | BK15: 0.859 | BL15: 0.804
A16: Mitstas IDLE ENABLED | B16: 3 | C16: Mitstas IDLE ENABLED | D16: 39.79 | E16: 0 | F16: 2.66 | G16: 30.08 | H16: 180.4 | I16: 248.46 | J16: 0.84450278 | K16: 101385.44 | L16: 2097152 | M16: 3.7077 | N16: 9.44 | O16: 15.95 | P16: 52.36 | Q16: 62.94 | R16: 0.44990833 | S16: 1.2944111 | T16: 155400.87 | U16: 99.6 | V16: 2892 | X16: 0.939 | Y16: 0.85 | Z16: 0.846 | AA16: 0.849 | AB16: 0.856 | AC16: 0.854 | AD16: 0.845 | AE16: 0.858 | AF16: 0.833 | AG16: 0.839 | AH16: 0.85 | AI16: 0.842 | AJ16: 0.859 | AK16: 0.838 | AL16: 0.839 | AM16: 0.849 | AN16: 0.822 | AO16: 0.856 | AP16: 0.854 | AQ16: 0.832 | AR16: 0.857 | AS16: 0.844 | AT16: 0.86 | AU16: 0.863 | AV16: 0.855 | AW16: 0.844 | AX16: 0.845 | AY16: 0.84 | AZ16: 0.854 | BA16: 0.82 | BB16: 0.853 | BC16: 0.854 | BD16: 0.849 | BE16: 0.849 | BF16: 0.842 | BG16: 0.837 | BH16: 0.854 | BI16: 0.842 | BJ16: 0.848 | BK16: 0.841 | BL16: 0.783
A17: GTweaks Power Plan V3 | B17: 1 | C17: GTweaks Power Plan V3 | D17: 39.8 | E17: 0 | F17: 4.88 | G17: 29.7 | H17: 172.19 | I17: 247.64 | J17: 0.87568919 | K17: 107956.38 | L17: 512 | M17: 3.4617 | N17: 9.49 | O17: 15.91 | P17: 51.09 | Q17: 62.81 | R17: 0.44134865 | S17: 1.3170378 | T17: 162366.26 | U17: 99.6 | V17: 2892 | X17: 0.892 | Y17: 0.891 | Z17: 0.897 | AA17: 0.898 | AB17: 0.886 | AC17: 0.899 | AD17: 0.893 | AE17: 0.899 | AF17: 0.887 | AG17: 0.896 | AH17: 0.895 | AI17: 0.901 | AJ17: 0.9 | AK17: 0.903 | AL17: 0.891 | AM17: 0.884 | AN17: 0.889 | AO17: 1.019 | AP17: 0.933 | AQ17: 0.902 | AR17: 0.889 | AS17: 0.9 | AT17: 0.906 | AU17: 0.9 | AV17: 0.893 | AW17: 0.915 | AX17: 0.906 | AY17: 0.897 | AZ17: 0.886 | BA17: 0.913 | BB17: 0.902 | BC17: 0.897 | BD17: 0.892 | BE17: 0.891 | BF17: 0.9 | BG17: 0.894 | BH17: 0.894 | BI17: 0.898 | BJ17: 0.889 | BK17: 0.901 | BL17: 0.846 | BM17: 0
A18: GTweaks Power Plan V3 | B18: 2 | C18: GTweaks Power Plan V3 | D18: 39.82 | E18: 0 | F18: 5.02 | G18: 29.44 | H18: 172.43 | I18: 247.66 | J18: 0.88546216 | K18: 107080.7 | L18: 512 | M18: 3.3652 | N18: 9.55 | O18: 15.95 | P18: 51.39 | Q18: 62.81 | R18: 0.44481351 | S18: 1.3302757 | T18: 160870.08 | U18: 99.5 | V18: 2890 | X18: 0.75 | Y18: 0.899 | Z18: 0.904 | AA18: 0.89 | AB18: 0.882 | AC18: 0.904 | AD18: 0.897 | AE18: 0.896 | AF18: 0.87 | AG18: 0.909 | AH18: 0.896 | AI18: 0.904 | AJ18: 0.889 | AK18: 0.882 | AL18: 0.896 | AM18: 0.906 | AN18: 0.886 | AO18: 0.895 | AP18: 0.912 | AQ18: 0.907 | AR18: 0.961 | AS18: 0.905 | AT18: 0.901 | AU18: 0.894 | AV18: 0.881 | AW18: 0.892 | AX18: 0.898 | AY18: 0.88 | AZ18: 0.896 | BA18: 0.895 | BB18: 0.861 | BC18: 0.888 | BD18: 0.883 | BE18: 0.893 | BF18: 0.908 | BG18: 0.877 | BH18: 0.894 | BI18: 0.899 | BJ18: 0.879 | BK18: 0.886 | BL18: 0.837 | BM18: 0.603
A19: GTweaks Power Plan V3 | B19: 3 | C19: GTweaks Power Plan V3 | D19: 39.79 | E19: 0 | F19: 5.13 | G19: 29.38 | H19: 176.78 | I19: 248.12 | J19: 0.88481389 | K19: 106179.99 | L19: 512 | M19: 3.2931 | N19: 9.4 | O19: 15.96 | P19: 51.75 | Q19: 62.92 | R19: 0.44068056 | S19: 1.3254944 | T19: 159061.32 | U19: 99.3 | V19: 2885 | X19: 0.865 | Y19: 0.896 | Z19: 0.894 | AA19: 0.896 | AB19: 0.887 | AC19: 0.898 | AD19: 0.894 | AE19: 0.886 | AF19: 0.884 | AG19: 0.892 | AH19: 0.909 | AI19: 0.889 | AJ19: 0.877 | AK19: 0.907 | AL19: 0.894 | AM19: 0.89 | AN19: 0.884 | AO19: 0.895 | AP19: 0.898 | AQ19: 0.894 | AR19: 0.884 | AS19: 0.898 | AT19: 0.861 | AU19: 0.894 | AV19: 0.872 | AW19: 0.895 | AX19: 0.876 | AY19: 0.896 | AZ19: 0.869 | BA19: 0.879 | BB19: 0.885 | BC19: 0.875 | BD19: 0.869 | BE19: 0.87 | BF19: 0.892 | BG19: 0.894 | BH19: 0.872 | BI19: 0.88 | BJ19: 0.888 | BK19: 0.89 | BL19: 0.82
A20: RIP Tweaks Power Plan | B20: 1 | C20: RIP Tweaks Power Plan | D20: 39.8 | E20: 0 | F20: 3.13 | G20: 30.07 | H20: 183.37 | I20: 248.74 | J20: 0.82857222 | K20: 99457.253 | L20: 256 | M20: 3.7152 | N20: 9.19 | O20: 16.26 | P20: 53.09 | Q20: 63.06 | R20: 0.43525556 | S20: 1.2638278 | T20: 151702.69 | U20: 99.3 | V20: 2885 | X20: 0.826 | Y20: 0.847 | Z20: 0.845 | AA20: 0.83 | AB20: 0.826 | AC20: 0.827 | AD20: 0.797 | AE20: 0.807 | AF20: 0.797 | AG20: 0.819 | AH20: 0.822 | AI20: 0.823 | AJ20: 0.803 | AK20: 0.809 | AL20: 0.814 | AM20: 0.815 | AN20: 0.812 | AO20: 0.825 | AP20: 0.848 | AQ20: 0.841 | AR20: 0.837 | AS20: 0.848 | AT20: 0.842 | AU20: 0.849 | AV20: 0.814 | AW20: 0.819 | AX20: 0.828 | AY20: 0.854 | AZ20: 0.834 | BA20: 0.826 | BB20: 0.852 | BC20: 0.853 | BD20: 0.846 | BE20: 0.842 | BF20: 0.848 | BG20: 0.843 | BH20: 0.858 | BI20: 0.838 | BJ20: 0.828 | BK20: 0.844 | BL20: 0.766
A21: RIP Tweaks Power Plan | B21: 2 | C21: RIP Tweaks Power Plan | D21: 39.76 | E21: 0 | F21: 1.98 | G21: 29.79 | H21: 179.04 | I21: 248.37 | J21: 0.85071389 | K21: 102095.18 | L21: 512 | M21: 3.5672 | N21: 8.78 | O21: 15.86 | P21: 51.79 | Q21: 62.9 | R21: 0.45685556 | S21: 1.3075694 | T21: 156896.01 | U21: 99.4 | V21: 2888 | X21: 0.821 | Y21: 0.843 | Z21: 0.835 | AA21: 0.844 | AB21: 0.833 | AC21: 0.84 | AD21: 0.857 | AE21: 0.835 | AF21: 0.843 | AG21: 0.842 | AH21: 0.853 | AI21: 0.831 | AJ21: 0.839 | AK21: 0.83 | AL21: 0.858 | AM21: 0.845 | AN21: 0.847 | AO21: 0.845 | AP21: 0.853 | AQ21: 0.857 | AR21: 0.846 | AS21: 0.827 | AT21: 0.87 | AU21: 0.838 | AV21: 0.838 | AW21: 0.838 | AX21: 0.837 | AY21: 0.848 | AZ21: 0.848 | BA21: 0.83 | BB21: 0.86 | BC21: 0.854 | BD21: 0.844 | BE21: 0.85 | BF21: 0.854 | BG21: 0.858 | BH21: 0.847 | BI21: 0.889 | BJ21: 0.919 | BK21: 0.919 | BL21: 0.838
A22: RIP Tweaks Power Plan | B22: 3 | C22: RIP Tweaks Power Plan | D22: 39.78 | E22: 0 | F22: 2.72 | G22: 28.51 | H22: 159.67 | I22: 246.44 | J22: 0.83831389 | K22: 100648.36 | L22: 512 | M22: 3.2392 | N22: 10.09 | O22: 15.99 | P22: 52.03 | Q22: 62.92 | R22: 0.45468056 | S22: 1.2929944 | T22: 155223.71 | U22: 99.5 | V22: 2889 | X22: 0.82 | Y22: 0.832 | Z22: 0.83 | AA22: 0.839 | AB22: 0.82 | AC22: 0.849 | AD22: 0.823 | AE22: 0.831 | AF22: 0.848 | AG22: 0.834 | AH22: 0.842 | AI22: 0.83 | AJ22: 0.81 | AK22: 0.852 | AL22: 0.842 | AM22: 0.823 | AN22: 0.846 | AO22: 0.836 | AP22: 0.85 | AQ22: 0.845 | AR22: 0.84 | AS22: 0.847 | AT22: 0.839 | AU22: 0.843 | AV22: 0.86 | AW22: 0.843 | AX22: 0.848 | AY22: 0.84 | AZ22: 0.83 | BA22: 0.844 | BB22: 0.825 | BC22: 0.853 | BD22: 0.846 | BE22: 0.831 | BF22: 0.848 | BG22: 0.848 | BH22: 0.843 | BI22: 0.845 | BJ22: 0.849 | BK22: 0.829 | BL22: 0.768
A23: Bitsum Highest Performance | B23: 1 | C23: Bitsum Highest Performance | D23: 48.05 | E23: 0 | F23: 6.46 | G23: 30.09 | H23: 174.04 | I23: 247.93 | J23: 0.92320667 | K23: 111022.58 | L23: 512 | M23: 3.4758 | N23: 9.56 | O23: 16.75 | P23: 55.7 | Q23: 66.39 | R23: 0.46113333 | S23: 1.38434 | T23: 166480.13 | U23: 99.4 | V23: 2887 | X23: 0.909 | Y23: 0.908 | Z23: 0.92 | AA23: 0.9 | AB23: 0.911 | AC23: 0.921 | AD23: 0.944 | AE23: 0.902 | AF23: 0.897 | AG23: 0.896 | AH23: 0.913 | AI23: 0.928 | AJ23: 0.913 | AK23: 0.919 | AL23: 0.92 | AM23: 0.883 | AN23: 0.918 | AO23: 0.923 | AP23: 0.921 | AQ23: 0.901 | AR23: 0.938 | AS23: 0.918 | AT23: 0.92 | AU23: 0.917 | AV23: 0.908 | AW23: 0.906 | AX23: 0.917 | AY23: 0.926 | AZ23: 0.928 | BA23: 0.907 | BB23: 0.956 | BC23: 1.421 | BD23: 0.964 | BE23: 0.905 | BF23: 0.922 | BG23: 0.894 | BH23: 0.921 | BI23: 0.924 | BJ23: 0.921 | BK23: 0.906 | BL23: 0.913 | BM23: 0.909 | BN23: 0.919 | BO23: 0.891 | BP23: 0.9
A24: Bitsum Highest Performance | B24: 2 | C24: Bitsum Highest Performance | D24: 39.89 | E24: 0 | F24: 6.4 | G24: 30.19 | H24: 173.41 | I24: 247.98 | J24: 0.90027568 | K24: 108250.05 | L24: 512 | M24: 3.3129 | N24: 9.61 | O24: 18.7 | P24: 56.84 | Q24: 78.43 | R24: 0.44240811 | S24: 1.3426838 | T24: 161445.5 | U24: 99.5 | V24: 2890 | X24: 0.885 | Y24: 0.904 | Z24: 0.909 | AA24: 0.898 | AB24: 0.918 | AC24: 0.904 | AD24: 0.95 | AE24: 0.912 | AF24: 0.945 | AG24: 0.934 | AH24: 0.861 | AI24: 0.892 | AJ24: 0.913 | AK24: 0.904 | AL24: 0.835 | AM24: 0.868 | AN24: 0.898 | AO24: 0.914 | AP24: 0.885 | AQ24: 0.876 | AR24: 0.9 | AS24: 0.912 | AT24: 0.91 | AU24: 0.91 | AV24: 0.888 | AW24: 0.905 | AX24: 0.899 | AY24: 0.895 | AZ24: 0.907 | BA24: 0.913 | BB24: 0.929 | BC24: 0.911 | BD24: 0.894 | BE24: 0.899 | BF24: 0.899 | BG24: 0.928 | BH24: 0.911 | BI24: 0.926 | BJ24: 0.898 | BK24: 0.907 | BL24: 0.876 | BM24: 0.801
A25: Bitsum Highest Performance | B25: 3 | C25: Bitsum Highest Performance | D25: 39.79 | E25: 0 | F25: 5.75 | G25: 30.25 | H25: 176.99 | I25: 248.26 | J25: 0.91481081 | K25: 110146.15 | L25: 512 | M25: 3.55 | N25: 9.75 | O25: 17.28 | P25: 55.97 | Q25: 71.39 | R25: 0.45444595 | S25: 1.3692568 | T25: 164888.47 | U25: 99.5 | V25: 2889 | X25: 0.834 | Y25: 0.924 | Z25: 0.933 | AA25: 0.921 | AB25: 0.907 | AC25: 0.924 | AD25: 0.92 | AE25: 0.918 | AF25: 0.926 | AG25: 0.938 | AH25: 0.908 | AI25: 0.918 | AJ25: 0.911 | AK25: 0.929 | AL25: 0.924 | AM25: 0.917 | AN25: 0.91 | AO25: 0.908 | AP25: 0.935 | AQ25: 0.923 | AR25: 0.909 | AS25: 0.923 | AT25: 0.939 | AU25: 0.921 | AV25: 0.901 | AW25: 0.927 | AX25: 0.928 | AY25: 0.934 | AZ25: 0.876 | BA25: 0.918 | BB25: 0.909 | BC25: 0.914 | BD25: 0.913 | BE25: 0.94 | BF25: 0.927 | BG25: 0.927 | BH25: 0.918 | BI25: 0.902 | BJ25: 0.934 | BK25: 0.923 | BL25: 0.883 | BM25: 0.772
A26: CactusOS Absolute Performance | B26: 1 | C26: CactusOS Absolute Performance | D26: 39.84 | E26: 0 | F26: 3.2 | G26: 29.44 | H26: 175.21 | I26: 247.94 | J26: 0.85681081 | K26: 103577.44 | L26: 512 | M26: 3.4402 | N26: 9.41 | O26: 15.88 | P26: 50.47 | Q26: 62.77 | R26: 0.45572162 | S26: 1.3125324 | T26: 158674.85 | U26: 99.5 | V26: 2889 | X26: 0.752 | Y26: 0.691 | Z26: 0.656 | AA26: 0.895 | AB26: 0.883 | AC26: 0.919 | AD26: 0.871 | AE26: 0.88 | AF26: 0.877 | AG26: 0.875 | AH26: 0.877 | AI26: 0.881 | AJ26: 0.879 | AK26: 0.874 | AL26: 0.854 | AM26: 0.854 | AN26: 0.845 | AO26: 0.833 | AP26: 0.863 | AQ26: 0.863 | AR26: 0.854 | AS26: 0.861 | AT26: 0.853 | AU26: 0.855 | AV26: 0.85 | AW26: 0.846 | AX26: 0.861 | AY26: 0.994 | AZ26: 0.861 | BA26: 0.847 | BB26: 0.861 | BC26: 0.851 | BD26: 0.855 | BE26: 0.863 | BF26: 0.878 | BG26: 0.847 | BH26: 0.854 | BI26: 0.84 | BJ26: 0.856 | BK26: 0.847 | BL26: 0.835 | BM26: 0.588
A27: CactusOS Absolute Performance | B27: 2 | C27: CactusOS Absolute Performance | D27: 39.77 | E27: 0 | F27: 2.77 | G27: 29.69 | H27: 173.62 | I27: 247.85 | J27: 0.85506944 | K27: 102629.16 | L27: 512 | M27: 3.5872 | N27: 9.48 | O27: 15.91 | P27: 50.92 | Q27: 62.75 | R27: 0.45285556 | S27: 1.307925 | T27: 156982.46 | U27: 99.5 | V27: 2889 | X27: 0.823 | Y27: 0.855 | Z27: 0.854 | AA27: 0.838 | AB27: 0.849 | AC27: 0.861 | AD27: 0.863 | AE27: 0.859 | AF27: 0.854 | AG27: 0.837 | AH27: 0.853 | AI27: 0.846 | AJ27: 0.852 | AK27: 0.857 | AL27: 0.849 | AM27: 0.86 | AN27: 0.854 | AO27: 0.871 | AP27: 0.864 | AQ27: 0.855 | AR27: 0.84 | AS27: 0.854 | AT27: 0.852 | AU27: 0.856 | AV27: 0.86 | AW27: 0.854 | AX27: 0.855 | AY27: 0.856 | AZ27: 0.843 | BA27: 0.934 | BB27: 0.844 | BC27: 0.855 | BD27: 0.853 | BE27: 0.858 | BF27: 0.862 | BG27: 0.855 | BH27: 0.856 | BI27: 0.854 | BJ27: 0.86 | BK27: 0.868 | BL27: 0.779
A28: CactusOS Absolute Performance | B28: 3 | C28: CactusOS Absolute Performance | D28: 39.77 | E28: 0 | F28: 3.24 | G28: 29.39 | H28: 176.85 | I28: 248.13 | J28: 0.84241111 | K28: 101099.44 | L28: 512 | M28: 3.3712 | N28: 9.67 | O28: 15.96 | P28: 51.39 | Q28: 62.91 | R28: 0.449375 | S28: 1.2917861 | T28: 155030.16 | U28: 99.7 | V28: 2895 | X28: 0.844 | Y28: 0.852 | Z28: 0.851 | AA28: 0.849 | AB28: 0.85 | AC28: 0.873 | AD28: 0.833 | AE28: 0.709 | AF28: 0.85 | AG28: 0.855 | AH28: 0.861 | AI28: 0.859 | AJ28: 0.843 | AK28: 0.845 | AL28: 0.871 | AM28: 0.858 | AN28: 0.846 | AO28: 0.862 | AP28: 0.841 | AQ28: 0.846 | AR28: 0.846 | AS28: 0.85 | AT28: 0.832 | AU28: 0.854 | AV28: 0.846 | AW28: 0.833 | AX28: 0.846 | AY28: 0.866 | AZ28: 0.836 | BA28: 0.834 | BB28: 0.854 | BC28: 0.849 | BD28: 0.846 | BE28: 0.835 | BF28: 0.852 | BG28: 0.87 | BH28: 0.851 | BI28: 0.84 | BJ28: 0.848 | BK28: 0.842 | BL28: 0.744
A29: High performance | B29: 1 | C29: High performance | D29: 39.78 | E29: 0 | F29: 5.27 | G29: 29.43 | H29: 175.58 | I29: 248.08 | J29: 0.85902703 | K29: 105870.18 | L29: 512 | M29: 3.3764 | N29: 9.33 | O29: 15.96 | P29: 51.75 | Q29: 62.87 | R29: 0.42393514 | S29: 1.2829622 | T29: 158117.28 | U29: 99.5 | V29: 2889 | X29: 0.87 | Y29: 0.885 | Z29: 0.894 | AA29: 0.896 | AB29: 0.88 | AC29: 0.898 | AD29: 0.904 | AE29: 0.586 | AF29: 0.886 | AG29: 0.903 | AH29: 0.893 | AI29: 0.894 | AJ29: 0.891 | AK29: 0.891 | AL29: 0.904 | AM29: 0.891 | AN29: 0.883 | AO29: 0.898 | AP29: 0.885 | AQ29: 0.899 | AR29: 0.894 | AS29: 0.897 | AT29: 0.893 | AU29: 0.89 | AV29: 0.868 | AW29: 0.907 | AX29: 0.895 | AY29: 0.901 | AZ29: 0.894 | BA29: 0.911 | BB29: 0.919 | BC29: 0.891 | BD29: 0.9 | BE29: 0.882 | BF29: 0.865 | BG29: 0.905 | BH29: 0.89 | BI29: 0.885 | BJ29: 0.89 | BK29: 0.894 | BL29: 0.807 | BM29: 0
A30: High performance | B30: 2 | C30: High performance | D30: 39.76 | E30: 0 | F30: 4.15 | G30: 29.08 | H30: 175 | I30: 248 | J30: 0.893025 | K30: 107171.42 | L30: 2097152 | M30: 3.1721 | N30: 8.83 | O30: 15.87 | P30: 51.14 | Q30: 62.83 | R30: 0.44175 | S30: 1.334775 | T30: 160184.8 | U30: 99.6 | V30: 2892 | X30: 1.181 | Y30: 0.969 | Z30: 0.992 | AA30: 0.943 | AB30: 0.902 | AC30: 0.902 | AD30: 0.902 | AE30: 0.885 | AF30: 0.887 | AG30: 0.904 | AH30: 0.901 | AI30: 0.906 | AJ30: 0.895 | AK30: 0.889 | AL30: 0.89 | AM30: 0.89 | AN30: 0.878 | AO30: 0.905 | AP30: 0.899 | AQ30: 0.901 | AR30: 0.89 | AS30: 0.9 | AT30: 0.909 | AU30: 0.88 | AV30: 0.891 | AW30: 0.899 | AX30: 0.887 | AY30: 0.894 | AZ30: 0.9 | BA30: 0.883 | BB30: 0.9 | BC30: 0.882 | BD30: 0.907 | BE30: 0.875 | BF30: 0.894 | BG30: 0.9 | BH30: 0.899 | BI30: 0.893 | BJ30: 0.899 | BK30: 0.898 | BL30: 0.833
A31: High performance | B31: 3 | C31: High performance | D31: 39.75 | E31: 0 | F31: 5.24 | G31: 29.36 | H31: 178.31 | I31: 248.27 | J31: 0.88538889 | K31: 106263.23 | L31: 512 | M31: 3.2837 | N31: 9.32 | O31: 15.97 | P31: 51.84 | Q31: 62.89 | R31: 0.43689722 | S31: 1.3222861 | T31: 158698.68 | U31: 99.3 | V31: 2885 | X31: 0.862 | Y31: 0.896 | Z31: 0.901 | AA31: 0.895 | AB31: 0.887 | AC31: 0.883 | AD31: 0.89 | AE31: 0.893 | AF31: 0.882 | AG31: 0.897 | AH31: 0.875 | AI31: 0.88 | AJ31: 0.869 | AK31: 0.896 | AL31: 0.887 | AM31: 0.869 | AN31: 0.888 | AO31: 0.898 | AP31: 0.903 | AQ31: 0.894 | AR31: 0.892 | AS31: 0.893 | AT31: 0.889 | AU31: 0.897 | AV31: 0.874 | AW31: 0.852 | AX31: 0.888 | AY31: 0.872 | AZ31: 0.871 | BA31: 0.881 | BB31: 0.892 | BC31: 0.913 | BD31: 0.901 | BE31: 0.888 | BF31: 0.898 | BG31: 0.892 | BH31: 0.899 | BI31: 0.875 | BJ31: 0.894 | BK31: 0.903 | BL31: 0.806
A32: Rosca Tweaks v2 | B32: 1 | C32: Rosca Tweaks v2 | D32: 44.99 | E32: 0 | F32: 5.02 | G32: 30.02 | H32: 178.09 | I32: 248.21 | J32: 0.87505714 | K32: 107481.86 | L32: 256 | M32: 3.586 | N32: 9.4 | O32: 15.96 | P32: 52.39 | Q32: 62.94 | R32: 0.44087619 | S32: 1.3159333 | T32: 161634.27 | U32: 99.5 | V32: 2890 | X32: 0.867 | Y32: 0.892 | Z32: 0.903 | AA32: 0.887 | AB32: 0.906 | AC32: 0.903 | AD32: 0.895 | AE32: 0.892 | AF32: 0.885 | AG32: 0.903 | AH32: 0.898 | AI32: 0.878 | AJ32: 0.89 | AK32: 0.909 | AL32: 0.891 | AM32: 0.893 | AN32: 0.878 | AO32: 0.895 | AP32: 0.888 | AQ32: 0.886 | AR32: 0.885 | AS32: 0.869 | AT32: 0.886 | AU32: 0.901 | AV32: 0.887 | AW32: 0.89 | AX32: 0.906 | AY32: 0.902 | AZ32: 0.907 | BA32: 0.897 | BB32: 0.905 | BC32: 0.9 | BD32: 0.901 | BE32: 0.891 | BF32: 0.893 | BG32: 0.906 | BH32: 0.9 | BI32: 0.894 | BJ32: 0.897 | BK32: 0.911 | BL32: 0.895 | BM32: 0.957 | BN32: 0.897 | BO32: 0.894 | BP32: 0.9
A33: Rosca Tweaks v2 | B33: 2 | C33: Rosca Tweaks v2 | D33: 39.77 | E33: 0 | F33: 4.97 | G33: 29.71 | H33: 174.74 | I33: 247.87 | J33: 0.89442778 | K33: 107357.88 | L33: 256 | M33: 3.4871 | N33: 9.52 | O33: 15.96 | P33: 52.34 | Q33: 62.91 | R33: 0.45173611 | S33: 1.3461639 | T33: 161580.74 | U33: 99.6 | V33: 2891 | X33: 0.883 | Y33: 0.888 | Z33: 0.886 | AA33: 0.897 | AB33: 0.877 | AC33: 0.9 | AD33: 0.902 | AE33: 0.909 | AF33: 0.893 | AG33: 0.891 | AH33: 0.898 | AI33: 0.892 | AJ33: 0.882 | AK33: 0.899 | AL33: 0.892 | AM33: 0.896 | AN33: 0.912 | AO33: 0.898 | AP33: 0.876 | AQ33: 0.893 | AR33: 0.892 | AS33: 0.901 | AT33: 0.898 | AU33: 0.896 | AV33: 0.903 | AW33: 0.882 | AX33: 0.888 | AY33: 0.89 | AZ33: 0.877 | BA33: 0.896 | BB33: 0.889 | BC33: 0.882 | BD33: 0.908 | BE33: 0.902 | BF33: 0.909 | BG33: 0.922 | BH33: 0.901 | BI33: 0.893 | BJ33: 0.884 | BK33: 0.9 | BL33: 0.852
A34: Rosca Tweaks v2 | B34: 3 | C34: Rosca Tweaks v2 | D34: 39.76 | E34: 0 | F34: 5 | G34: 29.66 | H34: 176.43 | I34: 248.06 | J34: 0.89375556 | K34: 107291.05 | L34: 512 | M34: 3.4773 | N34: 9.54 | O34: 15.96 | P34: 52.51 | Q34: 62.96 | R34: 0.45163611 | S34: 1.3453917 | T34: 161512.41 | U34: 99.4 | V34: 2886 | X34: 0.868 | Y34: 0.892 | Z34: 0.904 | AA34: 0.897 | AB34: 0.896 | AC34: 0.908 | AD34: 0.894 | AE34: 0.912 | AF34: 0.875 | AG34: 0.906 | AH34: 0.906 | AI34: 0.888 | AJ34: 0.885 | AK34: 0.9 | AL34: 0.901 | AM34: 0.906 | AN34: 0.9 | AO34: 0.889 | AP34: 0.906 | AQ34: 0.909 | AR34: 0.902 | AS34: 0.887 | AT34: 0.883 | AU34: 0.907 | AV34: 0.883 | AW34: 0.877 | AX34: 0.911 | AY34: 0.893 | AZ34: 0.902 | BA34: 0.893 | BB34: 0.892 | BC34: 0.894 | BD34: 0.88 | BE34: 0.888 | BF34: 0.9 | BG34: 0.903 | BH34: 0.894 | BI34: 0.885 | BJ34: 0.895 | BK34: 0.905 | BL34: 0.815
A35: Ultimate Performance | B35: 1 | C35: Ultimate Performance | D35: 45.04 | E35: 0 | F35: 5.27 | G35: 29.89 | H35: 179.06 | I35: 248.36 | J35: 0.87847143 | K35: 106306.35 | L35: 512 | M35: 3.4579 | N35: 9.18 | O35: 16.18 | P35: 53.1 | Q35: 63.01 | R35: 0.43368333 | S35: 1.3121548 | T35: 158793.94 | U35: 99.4 | V35: 2886 | X35: 0.861 | Y35: 0.896 | Z35: 0.91 | AA35: 0.899 | AB35: 0.874 | AC35: 0.905 | AD35: 0.879 | AE35: 0.883 | AF35: 0.905 | AG35: 0.892 | AH35: 0.906 | AI35: 0.884 | AJ35: 0.871 | AK35: 0.901 | AL35: 0.894 | AM35: 0.889 | AN35: 0.889 | AO35: 0.868 | AP35: 0.888 | AQ35: 0.9 | AR35: 0.883 | AS35: 0.911 | AT35: 0.877 | AU35: 0.891 | AV35: 0.893 | AW35: 0.885 | AX35: 0.897 | AY35: 0.863 | AZ35: 0.886 | BA35: 0.906 | BB35: 0.9 | BC35: 0.904 | BD35: 0.913 | BE35: 0.878 | BF35: 0.893 | BG35: 0.894 | BH35: 0.902 | BI35: 0.895 | BJ35: 0.855 | BK35: 0.873 | BL35: 0.888 | BM35: 0.87 | BN35: 0.859 | BO35: 0.885 | BP35: 0.876
A36: Ultimate Performance | B36: 2 | C36: Ultimate Performance | D36: 39.77 | E36: 0 | F36: 5.28 | G36: 29.74 | H36: 179.37 | I36: 248.54 | J36: 0.88935833 | K36: 106769.98 | L36: 512 | M36: 3.4024 | N36: 9.23 | O36: 16.23 | P36: 52.93 | Q36: 63.01 | R36: 0.43811389 | S36: 1.3274722 | T36: 159367.52 | U36: 99.5 | V36: 2889 | X36: 0.88 | Y36: 0.897 | Z36: 0.893 | AA36: 0.908 | AB36: 0.881 | AC36: 0.893 | AD36: 0.915 | AE36: 0.891 | AF36: 0.887 | AG36: 0.893 | AH36: 0.901 | AI36: 0.901 | AJ36: 0.886 | AK36: 0.898 | AL36: 0.896 | AM36: 0.884 | AN36: 0.882 | AO36: 0.895 | AP36: 0.891 | AQ36: 0.89 | AR36: 0.882 | AS36: 0.879 | AT36: 0.899 | AU36: 0.882 | AV36: 0.889 | AW36: 0.879 | AX36: 0.881 | AY36: 0.901 | AZ36: 0.892 | BA36: 0.891 | BB36: 0.906 | BC36: 0.905 | BD36: 0.895 | BE36: 0.889 | BF36: 0.879 | BG36: 0.928 | BH36: 0.879 | BI36: 0.853 | BJ36: 0.909 | BK36: 0.889 | BL36: 0.804
A37: Ultimate Performance | B37: 3 | C37: Ultimate Performance | D37: 39.76 | E37: 0 | F37: 3.6 | G37: 29.35 | H37: 173.83 | I37: 247.82 | J37: 0.89991111 | K37: 108042.85 | L37: 512 | M37: 3.2279 | N37: 8.26 | O37: 15.84 | P37: 51.95 | Q37: 62.97 | R37: 0.44954722 | S37: 1.3494583 | T37: 162017.12 | U37: 99.5 | V37: 2889 | X37: 0.861 | Y37: 0.888 | Z37: 0.902 | AA37: 0.887 | AB37: 0.882 | AC37: 0.897 | AD37: 0.893 | AE37: 0.899 | AF37: 0.882 | AG37: 0.894 | AH37: 0.898 | AI37: 0.901 | AJ37: 0.885 | AK37: 0.896 | AL37: 0.891 | AM37: 0.906 | AN37: 0.888 | AO37: 0.866 | AP37: 0.911 | AQ37: 0.895 | AR37: 0.895 | AS37: 0.885 | AT37: 0.891 | AU37: 0.906 | AV37: 0.883 | AW37: 0.883 | AX37: 0.903 | AY37: 0.869 | AZ37: 0.891 | BA37: 0.862 | BB37: 0.885 | BC37: 0.919 | BD37: 0.905 | BE37: 0.945 | BF37: 0.992 | BG37: 0.976 | BH37: 0.957 | BI37: 0.929 | BJ37: 0.934 | BK37: 0.902 | BL37: 0.776
A38: VTRL Optimized | B38: 1 | C38: VTRL Optimized | D38: 40.52 | E38: 0 | F38: 3.93 | G38: 28.76 | H38: 173.96 | I38: 247.82 | J38: 0.77859459 | K38: 93504.283 | L38: 512 | M38: 3.4955 | N38: 8.82 | O38: 15.95 | P38: 53.26 | Q38: 63.05 | R38: 0.40294324 | S38: 1.1815378 | T38: 141883.83 | U38: 99.6 | V38: 2893 | X38: 0.745 | Y38: 0.762 | Z38: 0.764 | AA38: 0.811 | AB38: 0.789 | AC38: 0.766 | AD38: 0.754 | AE38: 0.78 | AF38: 0.795 | AG38: 0.77 | AH38: 0.762 | AI38: 0.794 | AJ38: 0.8 | AK38: 0.779 | AL38: 0.765 | AM38: 0.773 | AN38: 0.804 | AO38: 0.776 | AP38: 0.765 | AQ38: 0.794 | AR38: 0.773 | AS38: 0.792 | AT38: 0.755 | AU38: 0.788 | AV38: 0.803 | AW38: 0.756 | AX38: 0.763 | AY38: 0.802 | AZ38: 0.796 | BA38: 0.803 | BB38: 0.76 | BC38: 0.777 | BD38: 0.803 | BE38: 0.795 | BF38: 0.754 | BG38: 0.795 | BH38: 0.789 | BI38: 0.792 | BJ38: 0.795 | BK38: 0.761 | BL38: 0.799 | BM38: 0.68
A39: VTRL Optimized | B39: 2 | C39: VTRL Optimized | D39: 39.75 | E39: 0 | F39: 4.03 | G39: 28.83 | H39: 179.95 | I39: 248.39 | J39: 0.7835 | K39: 94031.833 | L39: 256 | M39: 3.2354 | N39: 8.9 | O39: 15.91 | P39: 53.2 | Q39: 63.01 | R39: 0.40468056 | S39: 1.1881806 | T39: 142595.94 | U39: 99.6 | V39: 2891 | X39: 0.733 | Y39: 0.765 | Z39: 0.774 | AA39: 0.772 | AB39: 0.764 | AC39: 0.779 | AD39: 0.791 | AE39: 0.808 | AF39: 0.757 | AG39: 0.799 | AH39: 0.796 | AI39: 0.787 | AJ39: 0.769 | AK39: 0.805 | AL39: 0.787 | AM39: 0.791 | AN39: 0.74 | AO39: 0.788 | AP39: 0.794 | AQ39: 0.788 | AR39: 0.78 | AS39: 0.769 | AT39: 0.785 | AU39: 0.809 | AV39: 0.773 | AW39: 0.768 | AX39: 0.795 | AY39: 0.794 | AZ39: 0.799 | BA39: 0.766 | BB39: 0.788 | BC39: 0.809 | BD39: 0.775 | BE39: 0.763 | BF39: 0.805 | BG39: 0.781 | BH39: 0.783 | BI39: 0.761 | BJ39: 0.803 | BK39: 0.796 | BL39: 0.727
A40: VTRL Optimized | B40: 3 | C40: VTRL Optimized | D40: 39.72 | E40: 0 | F40: 4 | G40: 28.69 | H40: 179.18 | I40: 248.34 | J40: 0.78269722 | K40: 93942.538 | L40: 512 | M40: 3.2628 | N40: 8.89 | O40: 15.92 | P40: 53 | Q40: 63.01 | R40: 0.40430556 | S40: 1.1870028 | T40: 142460.34 | U40: 99.4 | V40: 2888 | X40: 0.747 | Y40: 0.796 | Z40: 0.795 | AA40: 0.783 | AB40: 0.757 | AC40: 0.808 | AD40: 0.78 | AE40: 0.778 | AF40: 0.757 | AG40: 0.793 | AH40: 0.805 | AI40: 0.802 | AJ40: 0.756 | AK40: 0.805 | AL40: 0.785 | AM40: 0.798 | AN40: 0.791 | AO40: 0.741 | AP40: 0.802 | AQ40: 0.786 | AR40: 0.788 | AS40: 0.774 | AT40: 0.774 | AU40: 0.779 | AV40: 0.783 | AW40: 0.768 | AX40: 0.795 | AY40: 0.775 | AZ40: 0.791 | BA40: 0.784 | BB40: 0.79 | BC40: 0.794 | BD40: 0.783 | BE40: 0.769 | BF40: 0.801 | BG40: 0.794 | BH40: 0.78 | BI40: 0.763 | BJ40: 0.79 | BK40: 0.789 | BL40: 0.725
...

Sheet 4. Statistical Analysis
B2: Statistical Analysis - Per Power Plan (n = 3 repeated captures each)
B3: Live formulas from Sheet 3. Ranked by DPC p99 latency (lower = better). Delta% and Welch t-test are vs the best plan.
B5: Best plan (DPC p99) | E5: Worst plan | H5: Best->Worst spread | K5: Lowest interrupt load | N5: ANOVA (DPC p99)
B6: Kizzimo's Extreme Low Latency - 115 us | E6: AutoOS - 196 us | H6: 81 us (45%) | K6: ARSENZA LOW LATENCY (INTEL THREAD DIRECTOR FIX | N6: F=24.3, p=4e-30 -> differences real
A9: Rank | B9: Power Plan | C9: Type | D9: n | E9: DPC p99 mean (us) | F9: +/-SD | G9: CV % | H9: 95% CI +/- | I9: DPC p999 mean | J9: DPC %CPU busy | K9: DPC us/s | L9: DPC max band | M9: ISR p99 mean | N9: ISR %CPU busy | O9: Comb %CPU busy | P9: CPU eff MHz | Q9: Delta vs best (us) | R9: Delta vs best % | S9: Welch p vs best | T9: Sig? (p<.05) | U9: Repeat- ability
A10: 1 | B10: Kizzimo's Extreme Low Latency | C10: community | D10: 3 | E10: =AVERAGE('3. Raw Data'!H2:H4) -> 115.24667 | F10: =STDEV('3. Raw Data'!H2:H4) -> 0.096090235 | G10: =F10/E10*100 -> 0.083377887 | H10: =TINV(0.05,3-1)*F10/SQRT(3) -> 0.23870138 | I10: =AVERAGE('3. Raw Data'!I2:I4) -> 240.29333 | J10: =AVERAGE('3. Raw Data'!J2:J4) -> 1.4559099 | K10: =AVERAGE('3. Raw Data'!K2:K4) -> 179195.9 | L10: =AVERAGE('3. Raw Data'!L2:L4) -> 699392 | M10: =AVERAGE('3. Raw Data'!P2:P4) -> 51.95 | N10: =AVERAGE('3. Raw Data'!R2:R4) -> 0.42275676 | O10: =AVERAGE('3. Raw Data'!S2:S4) -> 1.8786667 | P10: =AVERAGE('3. Raw Data'!V2:V4) -> 2886.6667 | Q10: 0 | R10: 0 | S10: ref | T10: best | U10: =IF(G10<1,"Excellent",IF(G10<2,"Good",IF(G10<4,"Fair","Poor"))) -> Excellent
A11: 2 | B11: Lowest Latency | C11: community | D11: 3 | E11: =AVERAGE('3. Raw Data'!H5:H7) -> 161.03333 | F11: =STDEV('3. Raw Data'!H5:H7) -> 11.036677 | G11: =F11/E11*100 -> 6.8536597 | H11: =TINV(0.05,3-1)*F11/SQRT(3) -> 27.416625 | I11: =AVERAGE('3. Raw Data'!I5:I7) -> 246.61667 | J11: =AVERAGE('3. Raw Data'!J5:J7) -> 0.89516978 | K11: =AVERAGE('3. Raw Data'!K5:K7) -> 107697.56 | L11: =AVERAGE('3. Raw Data'!L5:L7) -> 512 | M11: =AVERAGE('3. Raw Data'!P5:P7) -> 56.803333 | N11: =AVERAGE('3. Raw Data'!R5:R7) -> 0.42494902 | O11: =AVERAGE('3. Raw Data'!S5:S7) -> 1.3201188 | P11: =AVERAGE('3. Raw Data'!V5:V7) -> 2889 | Q11: =E11-E10 -> 45.786667 | R11: =(E11-E10)/E10*100 -> 39.729276 | S11: =TTEST('3. Raw Data'!H5:H7,'3. Raw Data'!H2:H4,2,3) -> 0.018816263 | T11: =IF(S11<0.05,"yes","tie") -> yes | U11: =IF(G11<1,"Excellent",IF(G11<2,"Good",IF(G11<4,"Fair","Poor"))) -> Poor
A12: 3 | B12: _Reticle_ | C12: community | D12: 3 | E12: =AVERAGE('3. Raw Data'!H8:H10) -> 167.05333 | F12: =STDEV('3. Raw Data'!H8:H10) -> 10.576627 | G12: =F12/E12*100 -> 6.3312875 | H12: =TINV(0.05,3-1)*F12/SQRT(3) -> 26.273797 | I12: =AVERAGE('3. Raw Data'!I8:I10) -> 247.13333 | J12: =AVERAGE('3. Raw Data'!J8:J10) -> 0.85100135 | K12: =AVERAGE('3. Raw Data'!K8:K10) -> 102176.51 | L12: =AVERAGE('3. Raw Data'!L8:L10) -> 426.66667 | M12: =AVERAGE('3. Raw Data'!P8:P10) -> 55.263333 | N12: =AVERAGE('3. Raw Data'!R8:R10) -> 0.41908434 | O12: =AVERAGE('3. Raw Data'!S8:S10) -> 1.2700857 | P12: =AVERAGE('3. Raw Data'!V8:V10) -> 2889.3333 | Q12: =E12-E10 -> 51.806667 | R12: =(E12-E10)/E10*100 -> 44.952855 | S12: =TTEST('3. Raw Data'!H8:H10,'3. Raw Data'!H2:H4,2,3) -> 0.013604529 | T12: =IF(S12<0.05,"yes","tie") -> yes | U12: =IF(G12<1,"Excellent",IF(G12<2,"Good",IF(G12<4,"Fair","Poor"))) -> Poor
A13: 4 | B13: amit's low latency powerplan | C13: community | D13: 3 | E13: =AVERAGE('3. Raw Data'!H11:H13) -> 171.75 | F13: =STDEV('3. Raw Data'!H11:H13) -> 1.3763357 | G13: =F13/E13*100 -> 0.80135995 | H13: =TINV(0.05,3-1)*F13/SQRT(3) -> 3.4190075 | I13: =AVERAGE('3. Raw Data'!I11:I13) -> 247.60333 | J13: =AVERAGE('3. Raw Data'!J11:J13) -> 0.83897315 | K13: =AVERAGE('3. Raw Data'!K11:K13) -> 100718.69 | L13: =AVERAGE('3. Raw Data'!L11:L13) -> 512 | M13: =AVERAGE('3. Raw Data'!P11:P13) -> 51.72 | N13: =AVERAGE('3. Raw Data'!R11:R13) -> 0.39833704 | O13: =AVERAGE('3. Raw Data'!S11:S13) -> 1.2373102 | P13: =AVERAGE('3. Raw Data'!V11:V13) -> 2889 | Q13: =E13-E10 -> 56.503333 | R13: =(E13-E10)/E10*100 -> 49.028171 | S13: =TTEST('3. Raw Data'!H11:H13,'3. Raw Data'!H2:H4,2,3) -> 0.00018519649 | T13: =IF(S13<0.05,"yes","tie") -> yes | U13: =IF(G13<1,"Excellent",IF(G13<2,"Good",IF(G13<4,"Fair","Poor"))) -> Excellent
A14: 5 | B14: Mitstas IDLE ENABLED | C14: community | D14: 3 | E14: =AVERAGE('3. Raw Data'!H14:H16) -> 173.39333 | F14: =STDEV('3. Raw Data'!H14:H16) -> 11.154803 | G14: =F14/E14*100 -> 6.4332365 | H14: =TINV(0.05,3-1)*F14/SQRT(3) -> 27.710067 | I14: =AVERAGE('3. Raw Data'!I14:I16) -> 247.75667 | J14: =AVERAGE('3. Raw Data'!J14:J16) -> 0.85195556 | K14: =AVERAGE('3. Raw Data'!K14:K16) -> 102280.71 | L14: =AVERAGE('3. Raw Data'!L14:L16) -> 699306.67 | M14: =AVERAGE('3. Raw Data'!P14:P16) -> 55.283333 | N14: =AVERAGE('3. Raw Data'!R14:R16) -> 0.46980463 | O14: =AVERAGE('3. Raw Data'!S14:S16) -> 1.3217602 | P14: =AVERAGE('3. Raw Data'!V14:V16) -> 2893.3333 | Q14: =E14-E10 -> 58.146667 | R14: =(E14-E10)/E10*100 -> 50.454098 | S14: =TTEST('3. Raw Data'!H14:H16,'3. Raw Data'!H2:H4,2,3) -> 0.012041473 | T14: =IF(S14<0.05,"yes","tie") -> yes | U14: =IF(G14<1,"Excellent",IF(G14<2,"Good",IF(G14<4,"Fair","Poor"))) -> Poor
A15: 6 | B15: GTweaks Power Plan V3 | C15: community | D15: 3 | E15: =AVERAGE('3. Raw Data'!H17:H19) -> 173.8 | F15: =STDEV('3. Raw Data'!H17:H19) -> 2.5835441 | G15: =F15/E15*100 -> 1.4865041 | H15: =TINV(0.05,3-1)*F15/SQRT(3) -> 6.4178793 | I15: =AVERAGE('3. Raw Data'!I17:I19) -> 247.80667 | J15: =AVERAGE('3. Raw Data'!J17:J19) -> 0.88198841 | K15: =AVERAGE('3. Raw Data'!K17:K19) -> 107072.36 | L15: =AVERAGE('3. Raw Data'!L17:L19) -> 512 | M15: =AVERAGE('3. Raw Data'!P17:P19) -> 51.41 | N15: =AVERAGE('3. Raw Data'!R17:R19) -> 0.44228091 | O15: =AVERAGE('3. Raw Data'!S17:S19) -> 1.3242693 | P15: =AVERAGE('3. Raw Data'!V17:V19) -> 2889 | Q15: =E15-E10 -> 58.553333 | R15: =(E15-E10)/E10*100 -> 50.806965 | S15: =TTEST('3. Raw Data'!H17:H19,'3. Raw Data'!H2:H4,2,3) -> 0.00063846411 | T15: =IF(S15<0.05,"yes","tie") -> yes | U15: =IF(G15<1,"Excellent",IF(G15<2,"Good",IF(G15<4,"Fair","Poor"))) -> Good
A16: 7 | B16: RIP Tweaks Power Plan | C16: community | D16: 3 | E16: =AVERAGE('3. Raw Data'!H20:H22) -> 174.02667 | F16: =STDEV('3. Raw Data'!H20:H22) -> 12.620326 | G16: =F16/E16*100 -> 7.2519496 | H16: =TINV(0.05,3-1)*F16/SQRT(3) -> 31.350628 | I16: =AVERAGE('3. Raw Data'!I20:I22) -> 247.85 | J16: =AVERAGE('3. Raw Data'!J20:J22) -> 0.8392 | K16: =AVERAGE('3. Raw Data'!K20:K22) -> 100733.6 | L16: =AVERAGE('3. Raw Data'!L20:L22) -> 426.66667 | M16: =AVERAGE('3. Raw Data'!P20:P22) -> 52.303333 | N16: =AVERAGE('3. Raw Data'!R20:R22) -> 0.44893056 | O16: =AVERAGE('3. Raw Data'!S20:S22) -> 1.2881306 | P16: =AVERAGE('3. Raw Data'!V20:V22) -> 2887.3333 | Q16: =E16-E10 -> 58.78 | R16: =(E16-E10)/E10*100 -> 51.003644 | S16: =TTEST('3. Raw Data'!H20:H22,'3. Raw Data'!H2:H4,2,3) -> 0.01501643 | T16: =IF(S16<0.05,"yes","tie") -> yes | U16: =IF(G16<1,"Excellent",IF(G16<2,"Good",IF(G16<4,"Fair","Poor"))) -> Poor
A17: 8 | B17: Bitsum Highest Performance | C17: community | D17: 3 | E17: =AVERAGE('3. Raw Data'!H23:H25) -> 174.81333 | F17: =STDEV('3. Raw Data'!H23:H25) -> 1.9111864 | G17: =F17/E17*100 -> 1.0932727 | H17: =TINV(0.05,3-1)*F17/SQRT(3) -> 4.7476501 | I17: =AVERAGE('3. Raw Data'!I23:I25) -> 248.05667 | J17: =AVERAGE('3. Raw Data'!J23:J25) -> 0.91276438 | K17: =AVERAGE('3. Raw Data'!K23:K25) -> 109806.26 | L17: =AVERAGE('3. Raw Data'!L23:L25) -> 512 | M17: =AVERAGE('3. Raw Data'!P23:P25) -> 56.17 | N17: =AVERAGE('3. Raw Data'!R23:R25) -> 0.45266246 | O17: =AVERAGE('3. Raw Data'!S23:S25) -> 1.3654268 | P17: =AVERAGE('3. Raw Data'!V23:V25) -> 2888.6667 | Q17: =E17-E10 -> 59.566667 | R17: =(E17-E10)/E10*100 -> 51.686238 | S17: =TTEST('3. Raw Data'!H23:H25,'3. Raw Data'!H2:H4,2,3) -> 0.00033244113 | T17: =IF(S17<0.05,"yes","tie") -> yes | U17: =IF(G17<1,"Excellent",IF(G17<2,"Good",IF(G17<4,"Fair","Poor"))) -> Good
A18: 9 | B18: CactusOS Absolute Performance | C18: community | D18: 3 | E18: =AVERAGE('3. Raw Data'!H26:H28) -> 175.22667 | F18: =STDEV('3. Raw Data'!H26:H28) -> 1.6150645 | G18: =F18/E18*100 -> 0.92170018 | H18: =TINV(0.05,3-1)*F18/SQRT(3) -> 4.0120426 | I18: =AVERAGE('3. Raw Data'!I26:I28) -> 247.97333 | J18: =AVERAGE('3. Raw Data'!J26:J28) -> 0.85143046 | K18: =AVERAGE('3. Raw Data'!K26:K28) -> 102435.35 | L18: =AVERAGE('3. Raw Data'!L26:L28) -> 512 | M18: =AVERAGE('3. Raw Data'!P26:P28) -> 50.926667 | N18: =AVERAGE('3. Raw Data'!R26:R28) -> 0.45265073 | O18: =AVERAGE('3. Raw Data'!S26:S28) -> 1.3040812 | P18: =AVERAGE('3. Raw Data'!V26:V28) -> 2891 | Q18: =E18-E10 -> 59.98 | R18: =(E18-E10)/E10*100 -> 52.044889 | S18: =TTEST('3. Raw Data'!H26:H28,'3. Raw Data'!H2:H4,2,3) -> 0.00023070543 | T18: =IF(S18<0.05,"yes","tie") -> yes | U18: =IF(G18<1,"Excellent",IF(G18<2,"Good",IF(G18<4,"Fair","Poor"))) -> Excellent
A19: 10 | B19: High performance | C19: MSFT stock | D19: 3 | E19: =AVERAGE('3. Raw Data'!H29:H31) -> 176.29667 | F19: =STDEV('3. Raw Data'!H29:H31) -> 1.7675501 | G19: =F19/E19*100 -> 1.0025998 | H19: =TINV(0.05,3-1)*F19/SQRT(3) -> 4.3908378 | I19: =AVERAGE('3. Raw Data'!I29:I31) -> 248.11667 | J19: =AVERAGE('3. Raw Data'!J29:J31) -> 0.87914697 | K19: =AVERAGE('3. Raw Data'!K29:K31) -> 106434.94 | L19: =AVERAGE('3. Raw Data'!L29:L31) -> 699392 | M19: =AVERAGE('3. Raw Data'!P29:P31) -> 51.576667 | N19: =AVERAGE('3. Raw Data'!R29:R31) -> 0.43419412 | O19: =AVERAGE('3. Raw Data'!S29:S31) -> 1.3133411 | P19: =AVERAGE('3. Raw Data'!V29:V31) -> 2888.6667 | Q19: =E19-E10 -> 61.05 | R19: =(E19-E10)/E10*100 -> 52.973333 | S19: =TTEST('3. Raw Data'!H29:H31,'3. Raw Data'!H2:H4,2,3) -> 0.00026897654 | T19: =IF(S19<0.05,"yes","tie") -> yes | U19: =IF(G19<1,"Excellent",IF(G19<2,"Good",IF(G19<4,"Fair","Poor"))) -> Good
A20: 11 | B20: Rosca Tweaks v2 | C20: community | D20: 3 | E20: =AVERAGE('3. Raw Data'!H32:H34) -> 176.42 | F20: =STDEV('3. Raw Data'!H32:H34) -> 1.6750224 | G20: =F20/E20*100 -> 0.94945153 | H20: =TINV(0.05,3-1)*F20/SQRT(3) -> 4.1609863 | I20: =AVERAGE('3. Raw Data'!I32:I34) -> 248.04667 | J20: =AVERAGE('3. Raw Data'!J32:J34) -> 0.88774683 | K20: =AVERAGE('3. Raw Data'!K32:K34) -> 107376.93 | L20: =AVERAGE('3. Raw Data'!L32:L34) -> 341.33333 | M20: =AVERAGE('3. Raw Data'!P32:P34) -> 52.413333 | N20: =AVERAGE('3. Raw Data'!R32:R34) -> 0.4480828 | O20: =AVERAGE('3. Raw Data'!S32:S34) -> 1.3358296 | P20: =AVERAGE('3. Raw Data'!V32:V34) -> 2889 | Q20: =E20-E10 -> 61.173333 | R20: =(E20-E10)/E10*100 -> 53.080349 | S20: =TTEST('3. Raw Data'!H32:H34,'3. Raw Data'!H2:H4,2,3) -> 0.0002393895 | T20: =IF(S20<0.05,"yes","tie") -> yes | U20: =IF(G20<1,"Excellent",IF(G20<2,"Good",IF(G20<4,"Fair","Poor"))) -> Excellent
A21: 12 | B21: Ultimate Performance | C21: MSFT stock | D21: 3 | E21: =AVERAGE('3. Raw Data'!H35:H37) -> 177.42 | F21: =STDEV('3. Raw Data'!H35:H37) -> 3.1128925 | G21: =F21/E21*100 -> 1.7545331 | H21: =TINV(0.05,3-1)*F21/SQRT(3) -> 7.7328538 | I21: =AVERAGE('3. Raw Data'!I35:I37) -> 248.24 | J21: =AVERAGE('3. Raw Data'!J35:J37) -> 0.88924696 | K21: =AVERAGE('3. Raw Data'!K35:K37) -> 107039.73 | L21: =AVERAGE('3. Raw Data'!L35:L37) -> 512 | M21: =AVERAGE('3. Raw Data'!P35:P37) -> 52.66 | N21: =AVERAGE('3. Raw Data'!R35:R37) -> 0.44044815 | O21: =AVERAGE('3. Raw Data'!S35:S37) -> 1.3296951 | P21: =AVERAGE('3. Raw Data'!V35:V37) -> 2888 | Q21: =E21-E10 -> 62.173333 | R21: =(E21-E10)/E10*100 -> 53.948053 | S21: =TTEST('3. Raw Data'!H35:H37,'3. Raw Data'!H2:H4,2,3) -> 0.00082619626 | T21: =IF(S21<0.05,"yes","tie") -> yes | U21: =IF(G21<1,"Excellent",IF(G21<2,"Good",IF(G21<4,"Fair","Poor"))) -> Good
A22: 13 | B22: VTRL Optimized | C22: community | D22: 3 | E22: =AVERAGE('3. Raw Data'!H38:H40) -> 177.69667 | F22: =STDEV('3. Raw Data'!H38:H40) -> 3.2588699 | G22: =F22/E22*100 -> 1.8339511 | H22: =TINV(0.05,3-1)*F22/SQRT(3) -> 8.0954817 | I22: =AVERAGE('3. Raw Data'!I38:I40) -> 248.18333 | J22: =AVERAGE('3. Raw Data'!J38:J40) -> 0.78159727 | K22: =AVERAGE('3. Raw Data'!K38:K40) -> 93826.218 | L22: =AVERAGE('3. Raw Data'!L38:L40) -> 426.66667 | M22: =AVERAGE('3. Raw Data'!P38:P40) -> 53.153333 | N22: =AVERAGE('3. Raw Data'!R38:R40) -> 0.40397645 | O22: =AVERAGE('3. Raw Data'!S38:S40) -> 1.1855737 | P22: =AVERAGE('3. Raw Data'!V38:V40) -> 2890.6667 | Q22: =E22-E10 -> 62.45 | R22: =(E22-E10)/E10*100 -> 54.188118 | S22: =TTEST('3. Raw Data'!H38:H40,'3. Raw Data'!H2:H4,2,3) -> 0.00089831897 | T22: =IF(S22<0.05,"yes","tie") -> yes | U22: =IF(G22<1,"Excellent",IF(G22<2,"Good",IF(G22<4,"Fair","Poor"))) -> Good
A23: 14 | B23: Sazinho Tweaks Latency Plan | C23: community | D23: 3 | E23: =AVERAGE('3. Raw Data'!H41:H43) -> 177.93333 | F23: =STDEV('3. Raw Data'!H41:H43) -> 11.537367 | G23: =F23/E23*100 -> 6.4840953 | H23: =TINV(0.05,3-1)*F23/SQRT(3) -> 28.660408 | I23: =AVERAGE('3. Raw Data'!I41:I43) -> 248.26333 | J23: =AVERAGE('3. Raw Data'!J41:J43) -> 0.83441204 | K23: =AVERAGE('3. Raw Data'!K41:K43) -> 100170.22 | L23: =AVERAGE('3. Raw Data'!L41:L43) -> 1398272 | M23: =AVERAGE('3. Raw Data'!P41:P43) -> 52.79 | N23: =AVERAGE('3. Raw Data'!R41:R43) -> 0.4440287 | O23: =AVERAGE('3. Raw Data'!S41:S43) -> 1.2784407 | P23: =AVERAGE('3. Raw Data'!V41:V43) -> 2889 | Q23: =E23-E10 -> 62.686667 | R23: =(E23-E10)/E10*100 -> 54.393475 | S23: =TTEST('3. Raw Data'!H41:H43,'3. Raw Data'!H2:H4,2,3) -> 0.011099344 | T23: =IF(S23<0.05,"yes","tie") -> yes | U23: =IF(G23<1,"Excellent",IF(G23<2,"Good",IF(G23<4,"Fair","Poor"))) -> Poor
A24: 15 | B24: Xilly's Public PowerPlan | C24: community | D24: 3 | E24: =AVERAGE('3. Raw Data'!H44:H46) -> 179.14667 | F24: =STDEV('3. Raw Data'!H44:H46) -> 0.78053401 | G24: =F24/E24*100 -> 0.43569552 | H24: =TINV(0.05,3-1)*F24/SQRT(3) -> 1.938954 | I24: =AVERAGE('3. Raw Data'!I44:I46) -> 248.34333 | J24: =AVERAGE('3. Raw Data'!J44:J46) -> 0.86403632 | K24: =AVERAGE('3. Raw Data'!K44:K46) -> 104502.78 | L24: =AVERAGE('3. Raw Data'!L44:L46) -> 512 | M24: =AVERAGE('3. Raw Data'!P44:P46) -> 53.06 | N24: =AVERAGE('3. Raw Data'!R44:R46) -> 0.42744387 | O24: =AVERAGE('3. Raw Data'!S44:S46) -> 1.2914802 | P24: =AVERAGE('3. Raw Data'!V44:V46) -> 2890.3333 | Q24: =E24-E10 -> 63.9 | R24: =(E24-E10)/E10*100 -> 55.446289 | S24: =TTEST('3. Raw Data'!H44:H46,'3. Raw Data'!H2:H4,2,3) -> 3.8940379e-05 | T24: =IF(S24<0.05,"yes","tie") -> yes | U24: =IF(G24<1,"Excellent",IF(G24<2,"Good",IF(G24<4,"Fair","Poor"))) -> Excellent
A25: 16 | B25: imribiy 2026 Power Plan | C25: community | D25: 3 | E25: =AVERAGE('3. Raw Data'!H47:H49) -> 179.91 | F25: =STDEV('3. Raw Data'!H47:H49) -> 1.845779 | G25: =F25/E25*100 -> 1.0259457 | H25: =TINV(0.05,3-1)*F25/SQRT(3) -> 4.5851691 | I25: =AVERAGE('3. Raw Data'!I47:I49) -> 248.43667 | J25: =AVERAGE('3. Raw Data'!J47:J49) -> 0.83519666 | K25: =AVERAGE('3. Raw Data'!K47:K49) -> 101095.95 | L25: =AVERAGE('3. Raw Data'!L47:L49) -> 512 | M25: =AVERAGE('3. Raw Data'!P47:P49) -> 51.623333 | N25: =AVERAGE('3. Raw Data'!R47:R49) -> 0.43803949 | O25: =AVERAGE('3. Raw Data'!S47:S49) -> 1.2732362 | P25: =AVERAGE('3. Raw Data'!V47:V49) -> 2890.6667 | Q25: =E25-E10 -> 64.663333 | R25: =(E25-E10)/E10*100 -> 56.108637 | S25: =TTEST('3. Raw Data'!H47:H49,'3. Raw Data'!H2:H4,2,3) -> 0.00026222829 | T25: =IF(S25<0.05,"yes","tie") -> yes | U25: =IF(G25<1,"Excellent",IF(G25<2,"Good",IF(G25<4,"Fair","Poor"))) -> Good
A26: 17 | B26: RevisionT Extreme Performance | C26: community | D26: 3 | E26: =AVERAGE('3. Raw Data'!H50:H52) -> 180.88667 | F26: =STDEV('3. Raw Data'!H50:H52) -> 0.3888873 | G26: =F26/E26*100 -> 0.21498948 | H26: =TINV(0.05,3-1)*F26/SQRT(3) -> 0.96604961 | I26: =AVERAGE('3. Raw Data'!I50:I52) -> 248.51333 | J26: =AVERAGE('3. Raw Data'!J50:J52) -> 0.84083981 | K26: =AVERAGE('3. Raw Data'!K50:K52) -> 100942.92 | L26: =AVERAGE('3. Raw Data'!L50:L52) -> 426.66667 | M26: =AVERAGE('3. Raw Data'!P50:P52) -> 52.52 | N26: =AVERAGE('3. Raw Data'!R50:R52) -> 0.44681667 | O26: =AVERAGE('3. Raw Data'!S50:S52) -> 1.2876565 | P26: =AVERAGE('3. Raw Data'!V50:V52) -> 2888.6667 | Q26: =E26-E10 -> 65.64 | R26: =(E26-E10)/E10*100 -> 56.956094 | S26: =TTEST('3. Raw Data'!H50:H52,'3. Raw Data'!H2:H4,2,3) -> 3.7161248e-06 | T26: =IF(S26<0.05,"yes","tie") -> yes | U26: =IF(G26<1,"Excellent",IF(G26<2,"Good",IF(G26<4,"Fair","Poor"))) -> Excellent
